Workbook

Sheet 实验完成情况2024-9
A1: 日期 | B1: 盒子里面位置 | C1: ID | D1: 存放位置 | F1: 已完成测序的样本 | K1: 三批样本的汇总在一起的完成情况（已完成实验，不确定是否都测序） | V1: 第一批样本的实际实验（加了T4PNK进行实验） | AB1: 第一批样本的实际实验（未加T4PNK） | AH1: 第一批样本的实际实验（未加T4PNK） | AO1: 第二批样本的实际实验（未加T4PNK） | AU1: 第三批样本的实际实验 （未加T4PNK）
A2: 2022年11月 | B2: A1 | C2: BF0002028E3 | D2: 4号冰箱#1-1-2-1 | F2: GDM20220907-V_AGCGTAGC | G2: G1127 | H2: HC-124-E3 | I2: TRUE | K2: G1127 | L2: HC-124-E3 | M2: 4号冰箱4-5-5-4 E6 | N2: S25 | O2: G1127 | V2: G1127 | W2: HC-124-E3 | X2: 4号冰箱4-5-5-4 E6 | Y2: S25 | AB2: G1353 | AC2: BF0001798 | AD2: #4号冰箱 4-5-5-2 H4 | AE2: S25 | AH2: G4764BX | AI2: HC-311-E3 | AJ2: 4号冰箱4-5-4-1号盒 | AK2: F9 | AL2: s41 | AO2: G2783 | AP2: BF0002028E3 | AQ2: A1 | AR2: S25 | AU2: G4911 | AV2: bf0004263e4 | AW2: I3 | AX2: #4号冰箱1-2-4-2 | AY2: s41
A3: 2022年11月 | B3: A2 | C3: SVC001522E5 | D3: 4号冰箱#1-1-2-1 | F3: GDM20220907-V_AGGAGTCC | G3: G1132 | H3: BF0001157 | I3: TRUE | K3: G1128 | L3: HC-119-E3 | O3: G1128 | V3: G1128 | W3: HC-119-E3 | AB3: G1354 | AC3: BF0002584 | AH3: G4765BX | AI3: HC-274-E3 | AK3: D3 | AL3: s43 | AO3: G2784 | AP3: SVC001522E5 | AU3: G4912 | AV3: bf0000612e1 | AW3: G8 | AY3: s43
A4: 2022年11月 | B4: A3 | C4: BF0004044E2 | D4: 4号冰箱#1-1-2-1 | F4: GDM20220907-V_CATGCCTA | G4: G1133 | H4: HC-196-E3 | I4: TRUE | K4: G1129 | L4: BF0001169 | M4: 4号冰箱4-5-5-3 G6 | N4: s39 | O4: G1129 | V4: G1129 | W4: BF0001169 | X4: 4号冰箱4-5-5-3 G6 | Y4: s39 | AB4: G1355 | AC4: BF0002480 | AD4: #4号冰箱 4-5-5-2 G4 | AE4: s39 | AH4: G4766BX | AI4: HC-72-E3 | AK4: D5 | AL4: s45 | AO4: G2785 | AP4: BF0004044E2 | AQ4: A3 | AR4: s39 | AU4: G4913 | AV4: bf0000522e2 | AW4: B1 | AY4: s45
A5: 2022年11月 | B5: A4 | C5: BF000001097E3 | D5: 4号冰箱#1-1-2-1 | F5: GDM20220907-V_CTAGTACG | G5: G1129 | H5: BF0001169 | I5: TRUE | K5: G1130 | L5: BF0001696 | M5: 4号冰箱4-5-5-3 F2 | N5: s41 | O5: G1130 | V5: G1130 | W5: BF0001696 | X5: 4号冰箱4-5-5-3 F2 | Y5: s41 | AB5: G1356 | AC5: BF0003027 | AD5: #4号冰箱 4-5-5-2 E5 | AE5: s41 | AH5: G4767BX | AI5: HC-347-E3 | AK5: C7 | AL5: s47 | AO5: G2786 | AP5: BF000001097E3 | AQ5: A4 | AR5: s41 | AU5: G4914 | AV5: bf0000569e1 | AW5: E5 | AY5: s47
A6: 2022年11月 | B6: A5 | C6: PA001658E2 | D6: 4号冰箱#1-1-2-1 | F6: GDM20220907-V_GCTCAGGA | G6: G1131 | H6: BF0001380 | I6: TRUE | K6: G1131 | L6: BF0001380 | M6: 4号冰箱4-5-4-2 E9 | N6: s43 | O6: G1131 | V6: G1131 | W6: BF0001380 | X6: 4号冰箱4-5-4-2 E9 | Y6: s43 | AB6: G1357 | AC6: BF0002300 | AD6: #4号冰箱 4-5-5-2 F6 | AE6: s43 | AH6: G4768BX | AI6: HC-275-E3 | AK6: C3 | AL6: S88 | AO6: G2787 | AP6: PA001658E2 | AQ6: A5 | AR6: s43 | AU6: G4915 | AV6: bf0000706e1 | AW6: D3 | AY6: S88
A7: 2022年11月 | B7: A6 | C7: BF00000633E1 | D7: 4号冰箱#1-1-2-1 | F7: GDM20220907-V_GTAGAGAG | G7: G1134 | H7: HC-288-E3 | I7: TRUE | K7: G1132 | L7: BF0001157 | M7: 4号冰箱4-5-4-2 G2 | N7: s45 | O7: G1132 | V7: G1132 | W7: BF0001157 | X7: 4号冰箱4-5-4-2 G2 | Y7: s45 | AB7: G1358 | AC7: BF0003114 | AD7: #4号冰箱 4-5-5-2 H3 | AE7: s45 | AH7: G4769BX | AI7: HC-250-E3 | AK7: C8 | AL7: S89 | AO7: G2788 | AP7: BF00000633E1 | AQ7: A6 | AR7: s45 | AU7: G4916 | AV7: bf0002185e3 | AW7: C4 | AY7: S89
A8: 2022年11月 | B8: A7 | C8: SVC002561E2 | D8: 4号冰箱#1-1-2-1 | F8: GDM20220907-V_TCGCCTTA | G8: G1128 | H8: HC-119-E3 | I8: TRUE | K8: G1133 | L8: HC-196-E3 | M8: 4号冰箱 4-5-4-4 D6 | N8: s47 | O8: G1133 | V8: G1133 | W8: HC-196-E3 | X8: 4号冰箱 4-5-4-4 D6 | Y8: s47 | AB8: G1359 | AC8: BF0001145 | AD8: #4号冰箱 4-5-5-2 F4 | AE8: s47 | AH8: G4770BX | AI8: BF0000740 | AK8: A9 | AL8: S90 | AO8: G2789 | AP8: SVC002561E2 | AQ8: A7 | AR8: s47 | AU8: G4917 | AV8: bf0001717e1 | AW8: G2 | AY8: S90
A9: 2022年11月 | B9: A8 | C9: BF00001125E2 | D9: 4号冰箱#1-1-2-1 | F9: GDM20220907-V_TTCTGCCT | G9: G1130 | H9: BF0001696 | I9: TRUE | K9: G1134 | L9: HC-288-E3 | M9: 4号冰箱 4-5-4-4 C5 | N9: s49 | O9: G1134 | V9: G1134 | W9: HC-288-E3 | X9: 4号冰箱 4-5-4-4 C5 | Y9: s49 | AB9: G1360 | AC9: B956 | AD9: #4号冰箱 4-5-5-2 G8 | AE9: s49 | AH9: G4771BX | AI9: BF0000703 | AK9: A7 | AL9: S91 | AO9: G2790 | AP9: BF00001125E2 | AQ9: A8 | AR9: s49 | AU9: G4918 | AV9: bf0001937e3 | AW9: E3 | AY9: S91
A10: 2022年11月 | B10: A9 | C10: BF0003212E3 | D10: 4号冰箱#1-1-2-1 | F10: GDM20220909-I_ACTGCATA | G10: G1139 | H10: BF0004570 | I10: TRUE | K10: G1135 | L10: BF0000594 | M10: 4号冰箱 4-5-4-2 G5 | N10: S88 | O10: G1135 | V10: G1135 | W10: BF0000594 | X10: 4号冰箱 4-5-4-2 G5 | Y10: S88 | AB10: G1361 | AC10: HC-75-E3 | AD10: #4号冰箱 4-5-5-4 F1 | AE10: S88 | AH10: G4772BX | AI10: BF0002092 | AJ10: 4号冰箱4-5-4-2号盒 | AK10: A8 | AL10: S92 | AO10: G2791 | AP10: BF0003212E3 | AQ10: A9 | AR10: S88 | AU10: G4919 | AV10: bf0001934e3 | AW10: A5 | AY10: S92
A11: 2022年11月 | B11: B1 | C11: BF0007603E1 | D11: 4号冰箱#1-1-2-1 | F11: GDM20220909-I_AGAGTAGA | G11: G1146 | H11: BF0000966 | I11: TRUE | K11: G1136 | L11: BF0002173 | M11: 4号冰箱 4-5-4-2 E7 | N11: S89 | O11: G1136 | V11: G1136 | W11: BF0002173 | X11: 4号冰箱 4-5-4-2 E7 | Y11: S89 | AB11: G1362 | AC11: HC-131-E3 | AD11: #4号冰箱 4-5-5-4 F5 | AE11: S89 | AH11: G4773BX | AI11: HC-71-E3 | AK11: E3 | AL11: S94 | AO11: G2792 | AP11: BF0007603E1 | AQ11: B1 | AR11: S89 | AU11: G4920 | AV11: bf0002315e1 | AW11: B7 | AY11: S94
A12: 2022年11月 | B12: B2 | C12: BF0005083E4 | D12: 4号冰箱#1-1-2-1 | F12: GDM20220909-I_CAGCCTCG | G12: G1136 | H12: BF0002173 | I12: TRUE | K12: G1137 | L12: SVC1686 | M12: 4号冰箱 4-5-4-2 G6 | N12: S90 | O12: G1137 | V12: G1137 | W12: SVC1686 | X12: 4号冰箱 4-5-4-2 G6 | Y12: S90 | AB12: G1363 | AC12: HC-171-E3 | AD12: #4号冰箱 4-5-5-4 F9 | AE12: S90 | AH12: G4774BX | AI12: HC-31-E3 | AK12: C8 | AL12: S95 | AO12: G2793 | AP12: BF0005083E4 | AQ12: B2 | AR12: S90 | AU12: G4921 | AV12: bf0002016e2 | AW12: D5 | AY12: S95
A13: 2022年11月 | B13: B3 | C13: PA001572E2 | D13: 4号冰箱#1-1-2-1 | F13: GDM20220909-I_CCTCTCTG | G13: G1135 | H13: BF0000594 | I13: TRUE | K13: G1138 | L13: BF0004044 | M13: 4号冰箱 4-5-4-2 G3 | N13: S91 | O13: G1138 | V13: G1138 | W13: BF0004044 | X13: 4号冰箱 4-5-4-2 G3 | Y13: S91 | AB13: G1364 | AC13: HC-168-E3 | AD13: #4号冰箱 4-5-5-4 F3 | AE13: S91 | AH13: G4775BX | AI13: HC-148-E3 | AK13: D3 | AL13: S96 | AO13: G2794 | AP13: PA001572E2 | AQ13: B3 | AR13: S91 | AU13: G4922 | AV13: bf0003496e2 | AW13: D1 | AY13: S96
A14: 2022年11月 | B14: B4 | C14: SVC001358E2 | D14: 4号冰箱#1-1-2-1 | F14: GDM20220909-I_CTCTCTAT | G14: G1145 | H14: BF0002531 | I14: TRUE | K14: G1139 | L14: BF0004570 | M14: 4号冰箱 4-5-4-2 F9 | N14: S92 | O14: G1139 | V14: G1139 | W14: BF0004570 | X14: 4号冰箱 4-5-4-2 F9 | Y14: S92 | AB14: G1365 | AC14: HC-45-E3 | AD14: #4号冰箱 4-5-5-3 G7 | AE14: S92 | AH14: G4776BX | AI14: BF0005386 | AK14: C6 | AL14: S97 | AO14: G2795 | AP14: SVC001358E2 | AQ14: B4 | AR14: S92 | AU14: G4923 | AV14: bf0000310e1 | AW14: A6 | AY14: S97
A15: 2022年11月 | B15: B5 | C15: B70001790E3 | D15: 4号冰箱#1-1-2-1 | F15: GDM20220909-I_GCGTAAGA | G15: G1143 | H15: BF0002684 | I15: TRUE | K15: G1140 | L15: SVC2232 | M15: 4号冰箱 4-5-4-2 H1 | N15: S93 | O15: G1140 | V15: G1140 | W15: SVC2232 | X15: 4号冰箱 4-5-4-2 H1 | Y15: S93 | AB15: G1366 | AC15: HC-239-E3 | AD15: #4号冰箱 4-5-5-3 H6 | AE15: S93 | AH15: G4777BX | AI15: BF0004371 | AK15: A6 | AL15: S98 | AO15: G2796 | AP15: B70001790E3 | AQ15: B5 | AR15: S93 | AU15: G4924 | AV15: svc002074e3 | AW15: H5 | AY15: S98
A16: 2022年11月 | B16: B6 | C16: SVC001734E2 | D16: 4号冰箱#1-1-2-1 | F16: GDM20220909-I_TAGATCGC | G16: G1144 | H16: BF0003462 | I16: TRUE | K16: G1141 | L16: SVC3319 | M16: 4号冰箱 4-5-4-2 G8 | N16: S94 | O16: G1141 | V16: G1141 | W16: SVC3319 | X16: 4号冰箱 4-5-4-2 G8 | Y16: S94 | AB16: G1367 | AC16: HC-56-E3 | AD16: #4号冰箱 4-5-5-3 I4 | AE16: S94 | AH16: G4778BX | AI16: BF0000115 | AK16: B8 | AL16: S99 | AO16: G2797 | AP16: SVC001734E2 | AQ16: B6 | AR16: S94 | AU16: G4925 | AV16: pa001953e1 | AW16: E2 | AY16: S99
A17: 2022年11月 | B17: B7 | C17: BF0002929E3 | D17: 4号冰箱#1-1-2-1 | F17: GDM20220909-I_TCCTCTAC | G17: G1138 | H17: BF0004044 | I17: TRUE | K17: G1142 | L17: BF0001471 | M17: 4号冰箱 4-5-4-2 E8 | N17: S95 | O17: G1142 | V17: G1142 | W17: BF0001471 | X17: 4号冰箱 4-5-4-2 E8 | Y17: S95 | AB17: G1368 | AC17: HC-184-E3 | AD17: #4号冰箱 4-5-5-3 I6 | AE17: S95 | AH17: G4779BX | AI17: HC-58-E3 | AK17: D2 | AL17: S25 | AO17: G2798 | AP17: BF0002929E3 | AQ17: B7 | AR17: S95 | AU17: G4926 | AV17: pa001973e1 | AW17: F2 | AY17: S25
A18: 2022年11月 | B18: B8 | C18: BF00000459E2 | D18: 4号冰箱#1-1-2-1 | F18: GDM20220909-I_TCTCTCCG | G18: G1142 | H18: BF0001471 | I18: TRUE | K18: G1143 | L18: BF0002684 | M18: 4号冰箱 4-5-4-2 F1 | N18: S96 | O18: G1143 | V18: G1143 | W18: BF0002684 | X18: 4号冰箱 4-5-4-2 F1 | Y18: S96 | AB18: G1369 | AC18: BF0002135 | AD18: #4号冰箱 4-5-5-2 F3 | AE18: S96 | AH18: G4780BX | AI18: HC-48-E3 | AK18: E4 | AL18: S37 | AO18: G2799 | AP18: BF00000459E2 | AQ18: B8 | AR18: S96 | AU18: G4927 | AV18: svc0001370e1 | AW18: G7 | AY18: S37
A19: 2022年11月 | B19: B9 | C19: BF0003334E3 | D19: 4号冰箱#1-1-2-1 | F19: GDM20220909-II_AGCGTAGC | G19: G1147 | H19: BF0002496 | I19: TRUE | K19: G1144 | L19: BF0003462 | M19: 4号冰箱 4-5-4-2 G1 | N19: S97 | O19: G1144 | V19: G1144 | W19: BF0003462 | X19: 4号冰箱 4-5-4-2 G1 | Y19: S97 | AB19: G1370 | AC19: BF0005181 | AD19: #4号冰箱 4-5-5-2 G3 | AE19: S97 | AH19: G4781BX | AI19: HC-141-E3 | AK19: E5 | AL19: s39 | AO19: G2800 | AP19: BF0003334E3 | AQ19: B9 | AR19: S97 | AU19: G4928 | AV19: svc0001381e2 | AW19: D8 | AY19: s39
A20: 2022年11月 | B20: C1 | C20: BF0001995E4 | D20: 4号冰箱#1-1-2-1 | F20: GDM20220909-II_AGGAGTCC | G20: G1152 | H20: BF0001447 | I20: TRUE | K20: G1145 | L20: BF0002531 | M20: 4号冰箱 4-5-4-2 G4 | N20: S98 | O20: G1145 | V20: G1145 | W20: BF0002531 | X20: 4号冰箱 4-5-4-2 G4 | Y20: S98 | AB20: G1371 | AC20: BF0003095 | AD20: #4号冰箱 4-5-5-2 F7 | AE20: S98 | AH20: G4782BX | AI20: HC-237-E3 | AK20: C7 | AL20: s41 | AO20: G2801 | AP20: BF0001995E4 | AQ20: C1 | AR20: S98 | AU20: G4929 | AV20: pa00001414e2 | AW20: G3 | AY20: s41
A21: 2022年11月 | B21: C2 | C21: BF0003671E2 | D21: 4号冰箱#1-1-2-1 | F21: GDM20220909-II_CAGCCTCG | G21: G1156 | H21: BF0003745 | I21: TRUE | K21: G1146 | L21: BF0000966 | M21: 4号冰箱 4-5-4-2 F5 | N21: S99 | O21: G1146 | V21: G1146 | W21: BF0000966 | X21: 4号冰箱 4-5-4-2 F5 | Y21: S99 | AB21: G1372 | AC21: BF0001428 | AD21: #4号冰箱 4-5-5-2 F9 | AE21: S99 | AH21: G4783BX | AI21: HC-127-E3 | AK21: D6 | AL21: s43 | AO21: G2802 | AP21: BF0003671E2 | AQ21: C2 | AR21: S99 | AU21: G4930 | AV21: pa00001427e2 | AW21: G5 | AY21: s43
A22: 2022年11月 | B22: C3 | C22: BF0003467E1 | D22: 4号冰箱#1-1-2-1 | F22: GDM20220909-II_CATGCCTA | G22: G1153 | H22: BF0001710 | I22: TRUE | K22: G1147 | L22: BF0002496 | M22: 4号冰箱 4-5-4-2 F3 | N22: S25 | O22: G1147 | V22: G1147 | W22: BF0002496 | X22: 4号冰箱 4-5-4-2 F3 | Y22: S25 | AB22: G1373 | AC22: BF0002530 | AD22: #4号冰箱 4-5-5-2 G7 | AE22: S25 | AH22: G4784BX | AI22: HC-73-E3 | AK22: E2 | AL22: s45 | AO22: G2803 | AP22: BF0003467E1 | AQ22: C3 | AR22: S25 | AU22: G4931 | AV22: svc0001510e1 | AW22: E8 | AY22: s45
... A26: 2022年11月 | B26: C7 | C26: BF0007125E4 | D26: 4号冰箱#1-1-2-1 | F26: GDM20220909-II_GTAAGGAG | G26: G1157 | H26: BF0007127 | I26: TRUE | K26: G1151 | L26: BF0006690 | M26: 4号冰箱 4-5-4-2 G7 | N26: s43 | O26: G1151 | V26: G1151 | W26: BF0006690 | X26: 4号冰箱 4-5-4-2 G7 | Y26: s43 | AB26: G1377 | AC26: HC-161-E3 | AD26: #4号冰箱 4-5-5-3 H7 | AE26: s43 | AH26: G4788 | AI26: HC-47-E3 | AK26: D8 | AL26: S90 | AO26: G2807 | AP26: BF0007125E4 | AQ26: C7 | AR26: s43 | AU26: G4935 | AV26: bf0003035e4 | AW26: D9 | AY26: S90
A27: 2022年11月 | B27: C8 | C27: PA002450E2 | D27: 4号冰箱#1-1-2-1 | F27: GDM20220909-II_GTAGAGAG | G27: G1154 | H27: BF0003930 | I27: TRUE | K27: G1152 | L27: BF0001447 | M27: 4号冰箱 4-5-4-2 F6 | N27: s45 | O27: G1152 | V27: G1152 | W27: BF0001447 | X27: 4号冰箱 4-5-4-2 F6 | Y27: s45 | AB27: G1378 | AC27: HC-188-E3 | AD27: #4号冰箱 4-5-5-3 H2 | AE27: s45 | AH27: G4789 | AI27: HC-251-E3 | AJ27: 4号冰箱4-5-4-4号盒 | AK27: B7 | AL27: S91 | AO27: G2808 | AP27: PA002450E2 | AQ27: C8 | AR27: s45 | AU27: G4936 | AV27: pa0001583e3 | AW27: A4 | AY27: S91
A28: 2022年11月 | B28: C9 | C28: SVC002254E4 | D28: 4号冰箱#1-1-2-1 | F28: GDM20220909-II_TCCTCTAC | G28: G1158 | H28: BF0007540 | I28: TRUE | K28: G1153 | L28: BF0001710 | M28: 4号冰箱 4-5-4-2 F8 | N28: s47 | O28: G1153 | V28: G1153 | W28: BF0001710 | X28: 4号冰箱 4-5-4-2 F8 | Y28: s47 | AB28: G1379 | AC28: HC-133-E3 | AD28: #4号冰箱 4-5-5-3 I2 | AE28: s47 | AH28: G4790 | AI28: HC-132-E3 | AK28: A1 | AL28: S92 | AO28: G2809 | AP28: SVC002254E4 | AQ28: C9 | AR28: s47 | AU28: G4937 | AV28: pa0001590e2 | AW28: F7 | AY28: S92
A29: 2022年11月 | B29: D1 | C29: BF0005442E5 | D29: 4号冰箱#1-1-2-1 | F29: GDM20220909-II_TCGCCTTA | G29: G1148 | H29: BF0001984 | I29: TRUE | K29: G1154 | L29: BF0003930 | M29: 4号冰箱 4-5-4-2 G9 | N29: s49 | O29: G1154 | V29: G1154 | W29: BF0003930 | X29: 4号冰箱 4-5-4-2 G9 | Y29: s49 | AB29: G1380 | AC29: HC-128-E3 | AD29: #4号冰箱 4-5-5-3 H5 | AE29: s49 | AH29: G4791 | AI29: HC-154-E3 | AK29: A9 | AL29: S94 | AO29: G2810 | AP29: BF0005442E5 | AQ29: D1 | AR29: s49 | AU29: G4938 | AV29: pa001785e2 | AW29: B4 | AY29: S94
A30: 2022年11月 | B30: D2 | C30: SVC00l619E5 | D30: 4号冰箱#1-1-2-1 | F30: GDM20220909-II_TTCTGCCT | G30: G1150 | H30: BF0005083 | I30: TRUE | K30: G1155 | L30: BF0003334 | M30: 4号冰箱 4-5-4-4 G3 | N30: S88 | O30: G1155 | V30: G1155 | W30: BF0003334 | X30: 4号冰箱 4-5-4-4 G3 | Y30: S88 | AB30: G1381 | AC30: HC-330-E3 | AD30: #4号冰箱 4-5-5-3 F7 | AE30: S88 | AH30: G4792 | AI30: HC-226-E3 | AK30: B1 | AL30: S95 | AO30: G2811 | AP30: SVC00l619E5 | AQ30: D2 | AR30: S88 | AU30: G4939 | AV30: bf0001646e4 | AW30: I9 | AY30: S95
A31: 2022年11月 | B31: D3 | C31: BF00001366E2 | D31: 4号冰箱#1-1-2-1 | F31: GDM20220910-I_AGCGTAGC | G31: G1183 | H31: HC-228-E3 | I31: TRUE | K31: G1156 | L31: BF0003745 | O31: G1156 | V31: G1156 | W31: BF0003745 | AB31: G1382 | AC31: HC-186-E3 | AD31: #4号冰箱 4-5-5-3 G4 | AE31: S89 | AH31: G4793 | AI31: HC-336-E3 | AK31: A6 | AL31: S96 | AO31: G2812 | AP31: BF00001366E2 | AQ31: D3 | AR31: S89 | AU31: G4940 | AV31: svc003166e4 | AW31: I2 | AY31: S96
A32: 2022年11月 | B32: D4 | C32: SVC002282E2 | D32: 4号冰箱#1-1-2-1 | F32: GDM20220910-I_AGGAGTCC | G32: G1188 | H32: HC-255-E3 | I32: TRUE | K32: G1157 | L32: BF0007127 | M32: 4号冰箱 4-5-4-4 G7 | N32: S90 | O32: G1157 | V32: G1157 | W32: BF0007127 | X32: 4号冰箱 4-5-4-4 G7 | Y32: S90 | AB32: G1383 | AC32: HC-326-E3 | AD32: #4号冰箱 4-5-5-3 F6 | AE32: S90 | AH32: G4794 | AI32: HC-158-E3 | AK32: A5 | AL32: S97 | AO32: G2813 | AP32: SVC002282E2 | AQ32: D4 | AR32: S90 | AU32: G4941 | AV32: bf0002036e1 | AW32: F3 | AY32: S97
A33: 2022年11月 | B33: D5 | C33: BF0002090E1 | D33: 4号冰箱#1-1-2-1 | F33: GDM20220910-I_CAGCCTCG | G33: G1192 | H33: HC-163-E3 | I33: TRUE | K33: G1158 | L33: BF0007540 | M33: 4号冰箱 4-5-4-4 E4 | N33: S91 | O33: G1158 | V33: G1158 | W33: BF0007540 | X33: 4号冰箱 4-5-4-4 E4 | Y33: S91 | AB33: G1384 | AC33: HC-256-E3 | AD33: #4号冰箱 4-5-5-3 E9 | AE33: S91 | AH33: G4795 | AI33: HC-118-E3 | AK33: A3 | AL33: S98 | AO33: G2814 | AP33: BF0002090E1 | AQ33: D5 | AR33: S91 | AU33: G4942 | AV33: bf0004159e2 | AW33: F4 | AY33: S98
C34: BF0004516E3 | F34: GDM20220910-I_CATGCCTA | G34: G1189 | H34: HC-214-E3 | I34: TRUE | K34: G1159 | L34: BF0000831 | M34: 4号冰箱 4-5-4-4 E5 | N34: S92 | O34: G1159 | V34: G1159 | W34: BF0000831 | X34: 4号冰箱 4-5-4-4 E5 | Y34: S92 | AB34: G1385 | AC34: BF0001202 | AD34: #4号冰箱 4-5-5-4 C3 | AE34: S92 | AH34: G4796 | AI34: HC-361-E3 | AK34: B4 | AL34: S99 | AO34: G2815 | AP34: BF0004516E3 | AQ34: D6 | AR34: S92 | AU34: G4943 | AV34: bf0003652e1 | AW34: F8 | AY34: S99
C35: BF0004484E1 | F35: GDM20220910-I_CCTCTCTG | G35: G1191 | H35: HC-341-E3 | I35: TRUE | K35: G1160 | L35: BF0003781 | M35: 4号冰箱 4-5-4-4 F3 | N35: S93 | O35: G1160 | V35: G1160 | W35: BF0003781 | X35: 4号冰箱 4-5-4-4 F3 | Y35: S93 | AB35: G1386 | AC35: BF0001732 | AH35: G4797 | AI35: HC-238-E3 | AK35: B2 | AL35: S25 | AO35: G2816 | AP35: BF0004484E1 | AQ35: D7 | AR35: S93 | AU35: G4944 | AV35: svc002278e4 | AW35: G8 | AY35: S25
A36: 2022年11月 | B36: D8 | C36: BF0005080E1 | D36: 4号冰箱#1-1-2-1 | F36: GDM20220910-I_CTAGTACG | G36: G1185 | H36: HC-339-E3 | I36: TRUE | K36: G1161 | L36: BF0004802 | M36: 4号冰箱 4-5-4-4 F2 | N36: S94 | O36: G1161 | V36: G1161 | W36: BF0004802 | X36: 4号冰箱 4-5-4-4 F2 | Y36: S94 | AB36: G1387 | AC36: BF0001917 | AD36: #4号冰箱 4-5-5-4 B7 | AE36: S94 | AH36: G4798 | AI36: BF0001728 | AJ36: 4号冰箱4-5-5-2号盒 | AK36: G9 | AL36: S37 | AO36: G2817 | AP36: BF0005080E1 | AQ36: D8 | AR36: S94 | AU36: G4945 | AV36: svc003252e6 | AW36: B5 | AY36: S37
A37: 2022年11月 | B37: D9 | C37: BF0003014E3 | D37: 4号冰箱#1-1-2-1 | F37: GDM20220910-I_GCTCAGGA | G37: G1187 | H37: HC-38-E3 | I37: TRUE | K37: G1162 | L37: BF0004516 | M37: 4号冰箱 4-5-4-4 E6 | N37: S95 | O37: G1162 | V37: G1162 | W37: BF0004516 | X37: 4号冰箱 4-5-4-4 E6 | Y37: S95 | AB37: G1388 | AC37: BF0001262 | AD37: #4号冰箱 4-5-5-4 A3 | AE37: S95 | AH37: G4799 | AI37: BF0002860 | AK37: H1 | AL37: s39 | AO37: G2818 | AP37: BF0003014E3 | AQ37: D9 | AR37: S95 | AU37: G4946 | AV37: svc003297e6 | AW37: H2 | AY37: s39
A38: 2022年11月 | B38: E1 | C38: SVC002350E8 | D38: 4号冰箱#1-1-2-1 | F38: GDM20220910-I_GTAAGGAG | G38: G1193 | H38: HC-164-E3 | I38: TRUE | K38: G1163 | L38: BF0003916 | M38: 4号冰箱 4-5-4-4 E9 | N38: S96 | O38: G1163 | V38: G1163 | W38: BF0003916 | X38: 4号冰箱 4-5-4-4 E9 | Y38: S96 | AB38: G1389 | AC38: B69 | AD38: #4号冰箱 4-5-5-4 B1 | AE38: S96 | AH38: G4800 | AI38: BF0000623 | AK38: H5 | AL38: s41 | AO38: G2819 | AP38: SVC002350E8 | AQ38: E1 | AR38: S96 | AU38: G4947 | AV38: bf0004542e2 | AW38: A8 | AY38: s41
A39: 2022年11月 | B39: E2 | C39: SVC002676E5 | D39: 4号冰箱#1-1-2-1 | F39: GDM20220910-I_GTAGAGAG | G39: G1190 | H39: HC-151-E3 | I39: TRUE | K39: G1164 | L39: BF0004068 | M39: 4号冰箱 4-5-4-4 F7 | N39: S97 | O39: G1164 | V39: G1164 | W39: BF0004068 | X39: 4号冰箱 4-5-4-4 F7 | Y39: S97 | AB39: G1390 | AC39: B1380 | AD39: #4号冰箱 4-5-5-4 A7 | AE39: S97 | AH39: G4801 | AI39: BF0002029 | AK39: H2 | AL39: s43 | AO39: G2820 | AP39: SVC002676E5 | AQ39: E2 | AR39: S97 | AU39: G4948 | AV39: svc002219e5 | AW39: H1 | AY39: s43
A40: 2022年11月 | B40: E3 | C40: BF0001584E1 | D40: 4号冰箱#1-1-2-1 | F40: GDM20220910-I_TCCTCTAC | G40: G1194 | H40: HC-92-E3 | I40: TRUE | K40: G1165 | L40: BF0002986 | M40: 4号冰箱 4-5-4-4 F6 | N40: S98 | O40: G1165 | V40: G1165 | W40: BF0002986 | X40: 4号冰箱 4-5-4-4 F6 | Y40: S98 | AB40: G1391 | AC40: BF0001394 | AD40: #4号冰箱 4-5-5-4 A5 | AE40: S98 | AH40: G4802 | AI40: BF0004130 | AK40: B6 | AL40: s45 | AO40: G2821 | AP40: BF0001584E1 | AQ40: E3 | AR40: S98 | AU40: G4949 | AV40: bf0003986e5 | AW40: H8 | AY40: s45
A41: 2022年11月 | B41: E4 | C41: BF0007540E1 | D41: 4号冰箱#1-1-2-1 | F41: GDM20220910-I_TCGCCTTA | G41: G1184 | H41: HC-270-E3 | I41: TRUE | K41: G1166 | L41: BF0004484 | M41: 4号冰箱 4-5-4-4 F4 | N41: S99 | O41: G1166 | V41: G1166 | W41: BF0004484 | X41: 4号冰箱 4-5-4-4 F4 | Y41: S99 | AB41: G1392 | AC41: BF0000073 | AD41: #4号冰箱 4-5-5-4 A6 | AE41: S99 | AH41: G4803 | AI41: BF0006368 | AK41: C4 | AL41: s47 | AO41: G2822 | AP41: BF0007540E1 | AQ41: E4 | AR41: S99 | AU41: G4950 | AV41: bf0005160e2 | AW41: D4 | AY41: s47
A42: 2022年11月 | B42: E5 | C42: PA002311E3 | D42: 4号冰箱#1-1-2-1 | F42: GDM20220910-I_TTCTGCCT | G42: G1186 | H42: HC-93-E3 | I42: TRUE | K42: G1167 | L42: BF0001071 | M42: 4号冰箱 4-5-4-4 G5 | N42: S25 | O42: G1167 | V42: G1167 | W42: BF0001071 | X42: 4号冰箱 4-5-4-4 G5 | Y42: S25 | AB42: G1393 | AC42: HC-289-E3 | AD42: #4号冰箱 4-5-5-3 F1 | AE42: S25 | AH42: G4804 | AI42: BF0004353 | AK42: C7 | AL42: S88 | AO42: G2823 | AP42: PA002311E3 | AQ42: E5 | AR42: S25 | AU42: G4951 | AV42: bf0001774e2 | AW42: E4 | AY42: S88
A43: 2022年11月 | B43: E6 | C43: SVC003250E4 | D43: 4号冰箱#1-1-2-1 | F43: GDM20220910-II_AAGGAGTA | G43: G1196 | H43: HC-153-E3 | I43: TRUE | K43: G1168 | L43: BF0000945 | M43: 4号冰箱 4-5-4-4 E8 | N43: S37 | O43: G1168 | V43: G1168 | W43: BF0000945 | X43: 4号冰箱 4-5-4-4 E8 | Y43: S37 | AB43: G1394 | AC43: HC-60-E3 | AD43: #4号冰箱 4-5-5-3 G3 | AE43: S37 | AH43: G4805 | AI43: BF0005270 | AK43: D8 | AL43: S89 | AO43: G2824 | AP43: SVC003250E4 | AQ43: E6 | AR43: S37 | AU43: G4952 | AV43: bf0001775e1 | AW43: A7 | AY43: S89
...

Sheet 临床信息统计
A1: 实验方法 | B1: 已完成建库+测序（2024-9） | C1: Library_ID | D1: 分类
A2: No T4PNK treatment | B2: TRUE | C2: GDM20230502-IV_AGCGTAGC | D2: IPAH/HPAH
A3: No T4PNK treatment | B3: TRUE | C3: GDM20230502-IV_TCGCCTTA | D3: IPAH/HPAH
A4: No T4PNK treatment | B4: TRUE | C4: GDM20230502-IV_CTAGTACG | D4: IPAH/HPAH
A5: No T4PNK treatment | B5: TRUE | C5: GDM20230502-IV_TTCTGCCT | D5: IPAH/HPAH
A6: No T4PNK treatment | B6: TRUE | C6: GDM20230502-IV_GCTCAGGA | D6: IPAH/HPAH
A7: No T4PNK treatment | B7: TRUE | C7: GDM20230502-IV_AGGAGTCC | D7: IPAH/HPAH
A8: No T4PNK treatment | B8: TRUE | C8: GDM20230502-IV_CATGCCTA | D8: IPAH/HPAH
A9: No T4PNK treatment | B9: TRUE | C9: GDM20230502-V_GTAGAGAG | D9: IPAH/HPAH
A10: No T4PNK treatment | B10: TRUE | C10: GDM20230502-V_CCTCTCTG | D10: IPAH/HPAH
A11: No T4PNK treatment | B11: TRUE | C11: GDM20230502-V_CAGCCTCG | D11: IPAH/HPAH
A12: No T4PNK treatment | B12: TRUE | C12: GDM20230502-V_GTAAGGAG | D12: IPAH/HPAH
A13: No T4PNK treatment | B13: TRUE | C13: GDM20230502-V_ACTGCATA | D13: IPAH/HPAH
... A110: No T4PNK treatment | B110: TRUE | C110: GDM20230530-II_CTAAGCCT | D110: IPAH/HPAH
A111: No T4PNK treatment | B111: TRUE | C111: GDM20230530-II_TCTCTCCG | D111: #N/A
A112: No T4PNK treatment | B112: TRUE | C112: GDM20230530-II_GCGTAAGA | D112: IPAH/HPAH
A113: No T4PNK treatment | B113: TRUE | C113: GDM20230530-II_CTCTCTAT | D113: IPAH/HPAH
A114: No T4PNK treatment | B114: TRUE | C114: GDM20230530-II_AGAGTAGA | D114: IPAH/HPAH
A115: No T4PNK treatment | B115: TRUE | C115: GDM20230530-III_TCGCCTTA | D115: IPAH/HPAH
A116: No T4PNK treatment | B116: TRUE | C116: GDM20230530-III_CTAGTACG | D116: IPAH/HPAH
A117: No T4PNK treatment | B117: TRUE | C117: GDM20230530-III_CATGCCTA | D117: IPAH/HPAH
A118: No T4PNK treatment | B118: TRUE | C118: GDM20230530-III_GTAGAGAG | D118: IPAH/HPAH
A119: No T4PNK treatment | B119: TRUE | C119: GDM20230530-III_CCTCTCTG | D119: IPAH/HPAH
A120: No T4PNK treatment | B120: TRUE | C120: GDM20230530-III_CAGCCTCG | D120: IPAH/HPAH
A121: No T4PNK treatment | B121: TRUE | C121: GDM20230530-III_GTAAGGAG | D121: IPAH/HPAH
A122: No T4PNK treatment | B122: TRUE | C122: GDM20230530-III_TCCTCTAC | D122: IPAH/HPAH
A123: No T4PNK treatment | B123: TRUE | C123: GDM20230530-III_ACTGCATA | D123: IPAH/HPAH
A124: No T4PNK treatment | B124: TRUE | C124: GDM20230530-III_AAGGAGTA | D124: #N/A
A125: No T4PNK treatment | B125: TRUE | C125: GDM20230530-III_CTAAGCCT | D125: IPAH/HPAH
A126: No T4PNK treatment | B126: TRUE | C126: GDM20230530-III_TCTCTCCG | D126: IPAH/HPAH
A127: No T4PNK treatment | B127: TRUE | C127: GDM20230530-IV_GCGTAAGA | D127: IPAH/HPAH
A128: No T4PNK treatment | B128: TRUE | C128: GDM20230530-IV_TAGATCGC | D128: IPAH/HPAH
A129: No T4PNK treatment | B129: TRUE | C129: GDM20230530-IV_CTCTCTAT | D129: IPAH/HPAH
A130: No T4PNK treatment | B130: TRUE | C130: GDM20230530-IV_AGAGTAGA | D130: IPAH/HPAH
A131: No T4PNK treatment | B131: TRUE | C131: GDM20230530-IV_AGCGTAGC | D131: IPAH/HPAH
A132: No T4PNK treatment | B132: TRUE | C132: GDM20230530-IV_TTCTGCCT | D132: IPAH/HPAH
A133: No T4PNK treatment | B133: TRUE | C133: GDM20230530-IV_GCTCAGGA | D133: IPAH/HPAH
A134: No T4PNK treatment | B134: TRUE | C134: GDM20230530-IV_CATGCCTA | D134: IPAH/HPAH
A135: No T4PNK treatment | B135: TRUE | C135: GDM20230530-IV_GTAGAGAG | D135: IPAH/HPAH
A136: No T4PNK treatment | B136: TRUE | C136: GDM20230530-IV_TCCTCTAC | D136: IPAH/HPAH
...

Sheet 已完成建库但未见测序结果
A1: 日期 | B1: 盒子里面位置 | C1: ID | D1: 存放位置 | E1: Seq_ID
A2: 2022年11月 | B2: B3 | C2: PA001572E2 | D2: 4号冰箱#1-1-2-1 | E2: =VLOOKUP(C2,'实验完成情况2024-9'!$L$2:$O$721,4,FALSE) -> G2794 | F2: TRUE
A3: 2022年11月 | B3: C6 | C3: SVC003702E2 | D3: 4号冰箱#1-1-2-1 | E3: =VLOOKUP(C3,'实验完成情况2024-9'!$L$2:$O$721,4,FALSE) -> G2806 | F3: TRUE
A4: 2022年11月 | B4: C8 | C4: PA002450E2 | D4: 4号冰箱#1-1-2-1 | E4: =VLOOKUP(C4,'实验完成情况2024-9'!$L$2:$O$721,4,FALSE) -> G2808 | F4: TRUE
A5: 2022年11月 | B5: C9 | C5: SVC002254E4 | D5: 4号冰箱#1-1-2-1 | E5: =VLOOKUP(C5,'实验完成情况2024-9'!$L$2:$O$721,4,FALSE) -> G2809 | F5: TRUE
A6: 2022年11月 | B6: D4 | C6: SVC002282E2 | D6: 4号冰箱#1-1-2-1 | E6: =VLOOKUP(C6,'实验完成情况2024-9'!$L$2:$O$721,4,FALSE) -> G2813 | F6: TRUE
A7: 2022年11月 | B7: E1 | C7: SVC002350E8 | D7: 4号冰箱#1-1-2-1 | E7: =VLOOKUP(C7,'实验完成情况2024-9'!$L$2:$O$721,4,FALSE) -> G2819 | F7: TRUE
A8: 2022年11月 | B8: E6 | C8: SVC003250E4 | D8: 4号冰箱#1-1-2-1 | E8: =VLOOKUP(C8,'实验完成情况2024-9'!$L$2:$O$721,4,FALSE) -> G2824 | F8: TRUE
A9: 2022年11月 | B9: E9 | C9: SVC001879E2 | D9: 4号冰箱#1-1-2-1 | E9: =VLOOKUP(C9,'实验完成情况2024-9'!$L$2:$O$721,4,FALSE) -> G2827 | F9: TRUE
A10: 2022年11月 | B10: F1 | C10: SVC002886E4 | D10: 4号冰箱#1-1-2-1 | E10: =VLOOKUP(C10,'实验完成情况2024-9'!$L$2:$O$721,4,FALSE) -> G2828 | F10: TRUE
A11: 2022年11月 | B11: F4 | C11: PA002671E1 | D11: 4号冰箱#1-1-2-1 | E11: =VLOOKUP(C11,'实验完成情况2024-9'!$L$2:$O$721,4,FALSE) -> G2831 | F11: TRUE
A12: 2022年11月 | B12: H7 | C12: PA001797E1 | D12: 4号冰箱#1-1-2-1 | E12: =VLOOKUP(C12,'实验完成情况2024-9'!$L$2:$O$721,4,FALSE) -> G2852 | F12: TRUE
A13: 2022年11月 | B13: H9 | C13: SVC003154E2 | D13: 4号冰箱#1-1-2-1 | E13: =VLOOKUP(C13,'实验完成情况2024-9'!$L$2:$O$721,4,FALSE) -> G2854 | F13: TRUE
... A42: 2022年11月 | B42: B6 | C42: PA001341E3 | D42: 4号冰箱#1-1-2-3 | E42: =VLOOKUP(C42,'实验完成情况2024-9'!$L$2:$O$721,4,FALSE) -> G2959 | F42: TRUE
A43: 2022年6月 | C43: HC-184-E3 | D43: 4号冰箱4-5-5-3 I6 | E43: =VLOOKUP(C43,'实验完成情况2024-9'!$L$2:$O$721,4,FALSE) -> G1368 | F43: TRUE
A44: 2022年6月 | C44: HC-161-E3 | D44: 4号冰箱4-5-5-3 H7 | E44: =VLOOKUP(C44,'实验完成情况2024-9'!$L$2:$O$721,4,FALSE) -> G1377 | F44: TRUE
A45: 2022年6月 | C45: HC-188-E3 | D45: 4号冰箱4-5-5-3 H2 | E45: =VLOOKUP(C45,'实验完成情况2024-9'!$L$2:$O$721,4,FALSE) -> G1378 | F45: TRUE
A46: 2022年6月 | C46: HC-39-E3 | D46: 4号冰箱4-5-5-3 G8 | E46: =VLOOKUP(C46,'实验完成情况2024-9'!$L$2:$O$721,4,FALSE) -> G4811 | F46: TRUE
A47: 2022年6月 | C47: HC-104-E3 | D47: 4号冰箱4-5-5-3 F5 | E47: =VLOOKUP(C47,'实验完成情况2024-9'!$L$2:$O$721,4,FALSE) -> G4812 | F47: TRUE
A48: 2022年6月 | C48: HC-256-E3 | D48: 4号冰箱4-5-5-3 E9 | E48: =VLOOKUP(C48,'实验完成情况2024-9'!$L$2:$O$721,4,FALSE) -> G1384 | F48: TRUE
A49: 2022年6月 | C49: HC-221-E3 | D49: 4号冰箱4-5-5-3 E8 | E49: =VLOOKUP(C49,'实验完成情况2024-9'!$L$2:$O$721,4,FALSE) -> G4818 | F49: TRUE
A50: 2022年6月 | C50: HC-193-E3 | D50: 4号冰箱4-5-5-4 F1 | E50: =VLOOKUP(C50,'实验完成情况2024-9'!$L$2:$O$721,4,FALSE) -> G1441 | F50: TRUE
A51: 2022年6月 | C51: HC-222-E3 | D51: 4号冰箱4-5-5-4 D6 | E51: =VLOOKUP(C51,'实验完成情况2024-9'!$L$2:$O$721,4,FALSE) -> G1442 | F51: TRUE
A52: 2022年6月 | C52: HC-335-E3 | D52: 4号冰箱4-5-5-4 C5 | E52: =VLOOKUP(C52,'实验完成情况2024-9'!$L$2:$O$721,4,FALSE) -> G1443 | F52: TRUE
A53: 2022年6月 | C53: BF0003027 | D53: 4号冰箱4-5-5-2 E5 | E53: =VLOOKUP(C53,'实验完成情况2024-9'!$L$2:$O$721,4,FALSE) -> G1356 | F53: TRUE
A54: 2022年6月 | C54: B956 | D54: 4号冰箱4-5-5-2 G8 | E54: =VLOOKUP(C54,'实验完成情况2024-9'!$L$2:$O$721,4,FALSE) -> G1360 | F54: TRUE
... A100: 2023年9月 | C100: pa001769e1 | D100: #5号冰箱4-4-5-3 B5 | E100: =VLOOKUP(C100,'实验完成情况2024-9'!$L$2:$O$721,4,FALSE) -> G5000 | F100: TRUE
A101: 2023年9月 | C101: pa001694e1 | D101: #N/A | E101: =VLOOKUP(C101,'实验完成情况2024-9'!$L$2:$O$721,4,FALSE) -> G5026 | F101: TRUE
A102: 2023年9月 | C102: svc003297e6 | D102: #4号冰箱1-2-4-4 H2 | E102: =VLOOKUP(C102,'实验完成情况2024-9'!$L$2:$O$721,4,FALSE) -> G4946 | F102: TRUE
A103: 2023年9月 | C103: bf0004155e2 | D103: #5号冰箱4-4-5-3 E9 | E103: =VLOOKUP(C103,'实验完成情况2024-9'!$L$2:$O$721,4,FALSE) -> G5009 | F103: TRUE
A104: 2023年9月 | C104: svc003008e5 | D104: #5号冰箱4-4-5-3 B4 | E104: =VLOOKUP(C104,'实验完成情况2024-9'!$L$2:$O$721,4,FALSE) -> G5020 | F104: TRUE

Sheet 临床信息统计-字符格式
A1: 寄送日期 | B1: 盒子里面位置 | C1: ID | D1: 冰箱存放位置 | E1: 实验方法 | F1: 已完成建库+测序（2024-9） | G1: 已完成建库，但未测序（2024-9） | H1: Library_ID | I1: seqID | J1: Sample type | K1: Clinical center | L1: Sample provider | M1: Specimen type | N1: Adapter | O1: I5 index | P1: Barcode | Q1: Sequence | R1: Reagent | S1: Library maker | T1: Library date | U1: Concentration (ng/ul) | V1: Volume (ul) | W1: Weight (ng) | X1: Seq batch | Y1: Seq date | Z1: Seq group | AA1: Platform | AB1: Gbase | AC1: Company | AD1: 出库批次 | AE1: 新的临床信息查询结果 | AF1: 样本编号简化 | AG1: 分类 | AH1: 编号 | AI1: 姓名 | AJ1: 采血日期 | AK1: 诊断 | AL1: 性别 | AM1: 年龄 | AN1: 六mwt | AO1: 心功能分级 | AP1: 体重rhc | AQ1: 身高rhc | AR1: 体表面积rhc | AS1: 超声测肺动脉收缩压 | AT1: 右心导管sbp | AU1: 右心导管dbp | AV1: 右心导管hr | AW1: 右心房压 | AX1: 肺动脉平均压 | AY1: 肺毛细血管楔压 | AZ1: 心输出量 | BA1: 心脏指数 | BB1: 肺血管阻力 | BC1: 混合静脉血氧饱和度 | BD1: APVT阳性 | BE1: ntprobnp | BF1: BNP | BG1: 肌酐 | BH1: 尿素氮 | BI1: 随访结果2021（0=存活，1=死亡，2=失访） | BJ1: 存活时间更新（月） | BK1: 随访备注 | BL1: 生存情况（1死亡，0存活） | BM1: 死亡时间更新 | BN1: 末次随访时间 | BO1: 起始用药（2=双药联合，3=三药联合，4=单药，0=未使用靶向药物） | BP1: 起始单药 | BQ1: 起始双药联合 | BR1: 起始三药联合 | BS1: 西地那非 | BT1: 伐地那非 | BU1: 他达那非 | BV1: 波生坦 | BW1: 安立生坦 | BX1: 伊洛前列素 | BY1: 贝前列素 | BZ1: 瑞莫杜林 | CA1: 地高辛 | CB1: 利尿补钾
A2: 2022年11月 | B2: A1 | C2: BF0002028E3 | D2: 4号冰箱#1-1-2-1 | E2: No T4PNK treatment | F2: TRUE | G2: FALSE | H2: GDM20230502-IV_AGCGTAGC | I2: G2783 | J2: 肺动脉高压 | K2: 北京协和医院 | L2: 荆志成 | M2: Plasma | N2: 0 | O2: 0 | P2: S25 | Q2: AGCGTAGC | R2: 0 | S2: LXY | T2: 20230426 | U2: 7.78 | V2: 3.8560411 | W2: 30 | X2: 179 | Y2: 20230502 | Z2: IV | AA2: Nova-seq | AB2: 0 | AC2: 海普洛斯 | AD2: 2022.11.11 | AE2: IPAH/HPAH | AF2: bf0002028 | AG2: IPAH/HPAH | AH2: b1600 | AI2: 吴晶晶 | AJ2: 42690 | AK2: ipah 分娩相关 | AL2: 2 | AM2: 28 | AN2: 467 | AO2: 2 | AP2: 60 | AQ2: 163 | AR2: 1.73 | AS2: 0 | AT2: 100 | AU2: 71 | AV2: 80 | AW2: 10 | AX2: 62 | AY2: 11 | AZ2: 3.67 | BA2: 2.12 | BB2: 13.9 | BC2: 56.6 | BD2: 0 | BE2: 0 | BF2: 0 | BG2: 0 | BH2: 0 | BI2: 0 | BJ2: 0 | BK2: 0 | BL2: 0 | BM2: 0 | BN2: 43818 | BO2: 0 | BP2: 0 | BQ2: 0 | BR2: 0 | BS2: 0 | BT2: 0 | BU2: 0 | BV2: 0 | BW2: 0 | BX2: 0 | BY2: 0 | BZ2: 0 | CA2: 0 | CB2: 0
A3: 2022年11月 | B3: A2 | C3: SVC001522E5 | D3: 4号冰箱#1-1-2-1 | E3: No T4PNK treatment | F3: TRUE | G3: FALSE | H3: GDM20230502-IV_TCGCCTTA | I3: G2784 | J3: 肺动脉高压 | K3: 北京协和医院 | L3: 荆志成 | M3: Plasma | N3: 0 | O3: 0 | P3: S37 | Q3: TCGCCTTA | R3: 0 | S3: LXY | T3: 20230426 | U3: 4.78 | V3: 6.2761506 | W3: 30 | X3: 179 | Y3: 20230502 | Z3: IV | AA3: Nova-seq | AB3: 0 | AC3: 海普洛斯 | AD3: 2022.11.11 | AE3: IPAH/HPAH | AF3: svc001522 | AG3: IPAH/HPAH | AH3: b3081 | AI3: 段晶晶 | AJ3: 42866 | AK3: 特发性肺动脉高压,心脏扩大,心功能Ⅱ级(NYHA分级) | AL3: 2 | AM3: 29 | AN3: 630 | AO3: 1 | AP3: 59 | AQ3: 168 | AR3: 1.75 | AS3: 0 | AT3: 119 | AU3: 67 | AV3: 80 | AW3: 9 | AX3: 53 | AY3: 12 | AZ3: 7.23 | BA3: 4.13 | BB3: 5.67 | BC3: 75.5 | BD3: 0 | BE3: 147 | BF3: 0 | BG3: 52.24 | BH3: 4 | BI3: 0 | BJ3: 48 | BK3: 0 | BL3: 0 | BM3: 0 | BN3: 43791 | BO3: 3 | BP3: 0 | BQ3: 0 | BR3: 1 | BS3: 0 | BT3: 0 | BU3: 1 | BV3: 0 | BW3: 1 | BX3: 0 | BY3: 1 | BZ3: 0 | CA3: 1 | CB3: 1
A4: 2022年11月 | B4: A3 | C4: BF0004044E2 | D4: 4号冰箱#1-1-2-1 | E4: No T4PNK treatment | F4: TRUE | G4: FALSE | H4: GDM20230502-IV_CTAGTACG | I4: G2785 | J4: 肺动脉高压 | K4: 北京协和医院 | L4: 荆志成 | M4: Plasma | N4: 0 | O4: 0 | P4: s39 | Q4: CTAGTACG | R4: 0 | S4: LXY | T4: 20230426 | U4: 9.64 | V4: 3.1120332 | W4: 30 | X4: 179 | Y4: 20230502 | Z4: IV | AA4: Nova-seq | AB4: 0 | AC4: 海普洛斯 | AD4: 2022.11.11 | AE4: IPAH/HPAH | AF4: bf0004044 | AG4: IPAH/HPAH | AH4: b3431 | AI4: 徐敏 | AJ4: 43040 | AK4: 特发性肺动脉高压,慢性肺源性心脏病,剖宫产个人史,心脏扩大,非风湿性三尖瓣关闭不全,心功能III级(NYHA分级),心包积液,甲状腺肿物,慢性乙型病毒性肝炎,肝囊肿,阑尾术后 | AL4: 2 | AM4: 26 | AN4: 378 | AO4: 2 | AP4: 60 | AQ4: 158 | AR4: 1.7 | AS4: 0 | AT4: 99 | AU4: 71 | AV4: 77 | AW4: 6 | AX4: 53 | AY4: 7 | AZ4: 3.63 | BA4: 2.14 | BB4: 12.67 | BC4: 68.6 | BD4: 0 | BE4: 1759 | BF4: 0 | BG4: 84.7 | BH4: 3.57 | BI4: 0 | BJ4: 42 | BK4: 0 | BL4: 0 | BM4: 0 | BN4: 43791 | BO4: 2 | BP4: 0 | BQ4: 1 | BR4: 0 | BS4: 0 | BT4: 0 | BU4: 1 | BV4: 0 | BW4: 1 | BX4: 0 | BY4: 0 | BZ4: 0 | CA4: 1 | CB4: 1
A5: 2022年11月 | B5: A4 | C5: BF0001097E3 | D5: 4号冰箱#1-1-2-1 | E5: No T4PNK treatment | F5: TRUE | G5: FALSE | H5: GDM20230502-IV_TTCTGCCT | I5: G2786 | J5: 肺动脉高压 | K5: 北京协和医院 | L5: 荆志成 | M5: Plasma | N5: 0 | O5: 0 | P5: s41 | Q5: TTCTGCCT | R5: 0 | S5: LXY | T5: 20230426 | U5: 6.42 | V5: 4.6728972 | W5: 30 | X5: 179 | Y5: 20230502 | Z5: IV | AA5: Nova-seq | AB5: 0 | AC5: 海普洛斯 | AD5: 0 | AE5: IPAH/HPAH | AF5: bf0001097 | AG5: IPAH/HPAH | AH5: b2077 | AI5: 朱燕梅 | AJ5: 42454 | AK5: hpha | AL5: 2 | AM5: 33 | AN5: 567 | AO5: 3 | AP5: 46 | AQ5: 162 | AR5: 1.55 | AS5: 0 | AT5: 99 | AU5: 60 | AV5: 66 | AW5: 3 | AX5: 43 | AY5: 7 | AZ5: 4.4 | BA5: 2.84 | BB5: 8.18 | BC5: 68.3 | BD5: 0 | BE5: 0 | BF5: 0 | BG5: 54.18 | BH5: 5.24 | BI5: 0 | BJ5: 0 | BK5: 0 | BL5: 0 | BM5: 0 | BN5: 0 | BO5: 0 | BP5: 0 | BQ5: 0 | BR5: 0 | BS5: 0 | BT5: 0 | BU5: 0 | BV5: 0 | BW5: 0 | BX5: 0 | BY5: 0 | BZ5: 0 | CA5: 0 | CB5: 0
A6: 2022年11月 | B6: A5 | C6: PA001658E2 | D6: 4号冰箱#1-1-2-1 | E6: No T4PNK treatment | F6: TRUE | G6: FALSE | H6: GDM20230502-IV_GCTCAGGA | I6: G2787 | J6: 肺动脉高压 | K6: 北京协和医院 | L6: 荆志成 | M6: Plasma | N6: 0 | O6: 0 | P6: s43 | Q6: GCTCAGGA | R6: 0 | S6: LXY | T6: 20230426 | U6: 1.88 | V6: 15.957447 | W6: 30 | X6: 179 | Y6: 20230502 | Z6: IV | AA6: Nova-seq | AB6: 0 | AC6: 海普洛斯 | AD6: 2022.11.11 | AE6: IPAH/HPAH | AF6: pa001658 | AG6: IPAH/HPAH | AH6: 2093 | AI6: 赵天祥 | AJ6: 42922 | AK6: ipah | AL6: 1 | AM6: 9 | AN6: 0 | AO6: 0 | AP6: 24 | AQ6: 135 | AR6: 1.11 | AS6: 0 | AT6: 98 | AU6: 66 | AV6: 71 | AW6: 10 | AX6: 71 | AY6: 9 | AZ6: 2.62 | BA6: 2.36 | BB6: 23.66 | BC6: 50.2 | BD6: 未见APVT试验 | BE6: 0 | BF6: 0 | BG6: 0 | BH6: 0 | BI6: 0 | BJ6: 0 | BK6: 0 | BL6: 0 | BM6: 0 | BN6: 0 | BO6: 0 | BP6: 0 | BQ6: 0 | BR6: 0 | BS6: 0 | BT6: 0 | BU6: 0 | BV6: 0 | BW6: 0 | BX6: 0 | BY6: 0 | BZ6: 0 | CA6: 0 | CB6: 0
A7: 2022年11月 | B7: A6 | C7: BF0000633E1 | D7: 4号冰箱#1-1-2-1 | E7: No T4PNK treatment | F7: TRUE | G7: FALSE | H7: GDM20230502-IV_AGGAGTCC | I7: G2788 | J7: 肺动脉高压 | K7: 北京协和医院 | L7: 荆志成 | M7: Plasma | N7: 0 | O7: 0 | P7: s45 | Q7: AGGAGTCC | R7: 0 | S7: LXY | T7: 20230426 | U7: 8.6 | V7: 3.4883721 | W7: 30 | X7: 179 | Y7: 20230502 | Z7: IV | AA7: Nova-seq | AB7: 0 | AC7: 海普洛斯 | AD7: 0 | AE7: IPAH/HPAH | AF7: bf0000633 | AG7: IPAH/HPAH | AH7: b1751 | AI7: 田娅涵 | AJ7: 42315 | AK7: IPAH可能 | AL7: 2 | AM7: 14月 | AN7: 0 | AO7: 0 | AP7: 0 | AQ7: 0 | AR7: 0 | AS7: 92 | AT7: 0 | AU7: 0 | AV7: 147 | AW7: 0 | AX7: 0 | AY7: 0 | AZ7: 0 | BA7: 0 | BB7: 0 | BC7: 0 | BD7: 0 | BE7: 0 | BF7: 0 | BG7: 0 | BH7: 0 | BI7: 0 | BJ7: 0 | BK7: 0 | BL7: 0 | BM7: 0 | BN7: 0 | BO7: 0 | BP7: 0 | BQ7: 0 | BR7: 0 | BS7: 0 | BT7: 0 | BU7: 0 | BV7: 0 | BW7: 0 | BX7: 0 | BY7: 0 | BZ7: 0 | CA7: 0 | CB7: 0
A8: 2022年11月 | B8: A7 | C8: SVC002561E2 | D8: 4号冰箱#1-1-2-1 | E8: No T4PNK treatment | F8: TRUE | G8: FALSE | H8: GDM20230502-IV_CATGCCTA | I8: G2789 | J8: 肺动脉高压 | K8: 北京协和医院 | L8: 荆志成 | M8: Plasma | N8: 0 | O8: 0 | P8: s47 | Q8: CATGCCTA | R8: 0 | S8: LXY | T8: 20230426 | U8: 2.36 | V8: 12.711864 | W8: 30 | X8: 179 | Y8: 20230502 | Z8: IV | AA8: Nova-seq | AB8: 0 | AC8: 海普洛斯 | AD8: 2022.11.11 | AE8: IPAH/HPAH | AF8: svc002561 | AG8: IPAH/HPAH | AH8: b3895 | AI8: 周水仙 | AJ8: 43230 | AK8: 可遗传性肺动脉高压,卵圆孔未闭,低血氧症,低钾血症,低钠血症,低蛋白血症,非新生儿高胆红素血症,慢性肺源性心脏病,心脏扩大,非风湿性三尖瓣关闭不全,心功能IV级(NYHA分级),阵发性心房颤动,阵发性心房扑动,高血压1级,2型糖尿病 | AL8: 2 | AM8: 58 | AN8: #NULL! | AO8: 2 | AP8: 45.2 | AQ8: 152 | AR8: 1.48 | AS8: 0 | AT8: 94 | AU8: 46 | AV8: 86 | AW8: 7 | AX8: 41 | AY8: 13 | AZ8: 3.63 | BA8: 2.46 | BB8: 7.71 | BC8: 43.4 | BD8: 未见APVT试验 | BE8: 45 | BF8: 0 | BG8: 77 | BH8: 8.32 | BI8: 1 | BJ8: 13 | BK8: 0 | BL8: 0 | BM8: 0 | BN8: 0 | BO8: 3 | BP8: 0 | BQ8: 0 | BR8: 1 | BS8: 0 | BT8: 0 | BU8: 1 | BV8: 0 | BW8: 1 | BX8: 0 | BY8: 0 | BZ8: 1 | CA8: 1 | CB8: 1
A9: 2022年11月 | B9: A8 | C9: BF0001125E2 | D9: 4号冰箱#1-1-2-1 | E9: No T4PNK treatment | F9: TRUE | G9: FALSE | H9: GDM20230502-V_GTAGAGAG | I9: G2790 | J9: 肺动脉高压 | K9: 北京协和医院 | L9: 荆志成 | M9: Plasma | N9: 0 | O9: 0 | P9: s49 | Q9: GTAGAGAG | R9: 0 | S9: LXY | T9: 20230427 | U9: 4.9 | V9: 6.122449 | W9: 30 | X9: 180 | Y9: 20230502 | Z9: V | AA9: Nova-seq | AB9: 0 | AC9: 海普洛斯 | AD9: 0 | AE9: IPAH/HPAH | AF9: bf0001125 | AG9: IPAH/HPAH | AH9: b2096 | AI9: 李海峰 | AJ9: 42462 | AK9: 风湿性心脏病，二尖瓣置换术后 pah | AL9: 1 | AM9: 39 | AN9: 445 | AO9: 3 | AP9: 95 | AQ9: 180 | AR9: 0 | AS9: 0 | AT9: 139 | AU9: 55 | AV9: 71 | AW9: 19 | AX9: 58 | AY9: 22 | AZ9: 10.47 | BA9: 4.61 | BB9: 3.44 | BC9: 65.2 | BD9: 0 | BE9: 0 | BF9: 0 | BG9: 87.97 | BH9: 6.33 | BI9: 0 | BJ9: 0 | BK9: 0 | BL9: 0 | BM9: 0 | BN9: 43791 | BO9: 0 | BP9: 0 | BQ9: 0 | BR9: 0 | BS9: 0 | BT9: 0 | BU9: 0 | BV9: 0 | BW9: 0 | BX9: 0 | BY9: 0 | BZ9: 0 | CA9: 0 | CB9: 0
A10: 2022年11月 | B10: A9 | C10: BF0003212E3 | D10: 4号冰箱#1-1-2-1 | E10: No T4PNK treatment | F10: TRUE | G10: FALSE | H10: GDM20230502-V_CCTCTCTG | I10: G2791 | J10: 肺动脉高压 | K10: 北京协和医院 | L10: 荆志成 | M10: Plasma | N10: 0 | O10: 0 | P10: S88 | Q10: CCTCTCTG | R10: 0 | S10: LXY | T10: 20230427 | U10: 5.28 | V10: 5.6818182 | W10: 30 | X10: 180 | Y10: 20230502 | Z10: V | AA10: Nova-seq | AB10: 0 | AC10: 海普洛斯 | AD10: 2022.11.11 | AE10: IPAH/HPAH | AF10: bf0003212 | AG10: IPAH/HPAH | AH10: b735 | AI10: 朱欢 | AJ10: 42922 | AK10: 肺动脉高压,心脏扩大,心功能Ⅱ级(NYHA分级) | AL10: 2 | AM10: 32 | AN10: 603 | AO10: 1 | AP10: 50 | AQ10: 161 | AR10: 1.59 | AS10: 0 | AT10: 104 | AU10: 60 | AV10: 72 | AW10: 4 | AX10: 42 | AY10: 7 | AZ10: 4.63 | BA10: 2.91 | BB10: 7.56 | BC10: 71.5 | BD10: 0 | BE10: 179 | BF10: 0 | BG10: 67.08 | BH10: 4 | BI10: 0 | BJ10: 42 | BK10: 0 | BL10: 0 | BM10: 0 | BN10: 43830 | BO10: 4 | BP10: 1 | BQ10: 0 | BR10: 0 | BS10: 0 | BT10: 0 | BU10: 0 | BV10: 0 | BW10: 1 | BX10: 0 | BY10: 0 | BZ10: 0 | CA10: 0 | CB10: 0
A11: 2022年11月 | B11: B1 | C11: BF0007603E1 | D11: 4号冰箱#1-1-2-1 | E11: No T4PNK treatment | F11: TRUE | G11: FALSE | H11: GDM20230502-V_CAGCCTCG | I11: G2792 | J11: 肺动脉高压 | K11: 北京协和医院 | L11: 荆志成 | M11: Plasma | N11: 0 | O11: 0 | P11: S89 | Q11: CAGCCTCG | R11: 0 | S11: LXY | T11: 20230427 | U11: 4.62 | V11: 6.4935065 | W11: 30 | X11: 180 | Y11: 20230502 | Z11: V | AA11: Nova-seq | AB11: 0 | AC11: 海普洛斯 | AD11: 2022.11.11 | AE11: IPAH/HPAH | AF11: bf0007603 | AG11: IPAH/HPAH | AH11: b5029 | AI11: 左红娜 | AJ11: 43690 | AK11: 特发性肺动脉高压，心脏扩大，三尖瓣轻中度关闭不全，心功能ii级，甲状腺结节 | AL11: 2 | AM11: 40 | AN11: 0 | AO11: 2 | AP11: 55 | AQ11: 161 | AR11: 1.65 | AS11: 0 | AT11: 105 | AU11: 70 | AV11: 68 | AW11: 3 | AX11: 55 | AY11: 13 | AZ11: 3.23 | BA11: 1.95 | BB11: 13 | BC11: 63.6 | BD11: 0 | BE11: 0 | BF11: 0 | BG11: 0 | BH11: 0 | BI11: 0 | BJ11: 0 | BK11: 0 | BL11: 0 | BM11: 0 | BN11: 0 | BO11: 0 | BP11: 0 | BQ11: 0 | BR11: 0 | BS11: 0 | BT11: 0 | BU11: 0 | BV11: 0 | BW11: 0 | BX11: 0 | BY11: 0 | BZ11: 0 | CA11: 0 | CB11: 0
A12: 2022年11月 | B12: B2 | C12: BF0005083E4 | D12: 4号冰箱#1-1-2-1 | E12: No T4PNK treatment | F12: TRUE | G12: FALSE | H12: GDM20230502-V_GTAAGGAG | I12: G2793 | J12: 肺动脉高压 | K12: 北京协和医院 | L12: 荆志成 | M12: Plasma | N12: 0 | O12: 0 | P12: S90 | Q12: GTAAGGAG | R12: 0 | S12: LXY | T12: 20230427 | U12: 8.14 | V12: 3.6855037 | W12: 30 | X12: 180 | Y12: 20230502 | Z12: V | AA12: Nova-seq | AB12: 0 | AC12: 海普洛斯 | AD12: 2022.11.11 | AE12: IPAH/HPAH | AF12: bf0005083 | AG12: IPAH/HPAH | AH12: b3936 | AI12: 鞠雯 | AJ12: 43240 | AK12: 特发性肺动脉高压,慢性肺源性心脏病,心脏扩大,心功能III级(NYHA分级),心包积液,甲状腺功能减退 | AL12: 2 | AM12: 35 | AN12: 468 | AO12: 2 | AP12: 57 | AQ12: 163 | AR12: 1.69 | AS12: 0 | AT12: 94 | AU12: 50 | AV12: 91 | AW12: 12 | AX12: 57 | AY12: 10 | AZ12: 3.53 | BA12: 2.09 | BB12: 13.31 | BC12: 57.9 | BD12: 未见APVT试验 | BE12: 6611 | BF12: 0 | BG12: 68 | BH12: 6.14 | BI12: 0 | BJ12: 36 | BK12: 0 | BL12: 0 | BM12: 0 | BN12: 43791 | BO12: 3 | BP12: 0 | BQ12: 0 | BR12: 1 | BS12: 0 | BT12: 0 | BU12: 1 | BV12: 0 | BW12: 1 | BX12: 0 | BY12: 0 | BZ12: 1 | CA12: 1 | CB12: 1
A13: 2022年11月 | B13: B4 | C13: SVC001358E2 | D13: 4号冰箱#1-1-2-1 | E13: No T4PNK treatment | F13: TRUE | G13: FALSE | H13: GDM20230502-V_ACTGCATA | I13: G2795 | J13: 肺动脉高压 | K13: 北京协和医院 | L13: 荆志成 | M13: Plasma | N13: 0 | O13: 0 | P13: S92 | Q13: ACTGCATA | R13: 0 | S13: LXY | T13: 20230427 | U13: 10.9 | V13: 2.7522936 | W13: 30 | X13: 180 | Y13: 20230502 | Z13: V | AA13: Nova-seq | AB13: 0 | AC13: 海普洛斯 | AD13: 2022.11.11 | AE13: IPAH/HPAH | AF13: svc001358 | AG13: IPAH/HPAH | AH13: b2253 | AI13: 李锐 | AJ13: 42796 | AK13: 特发性肺动脉高压,心脏扩大,心功能Ⅱ级(NYHA分级) | AL13: 2 | AM13: 27 | AN13: 470 | AO13: 1 | AP13: 53 | AQ13: 162 | AR13: 1.64 | AS13: 0 | AT13: 106 | AU13: 69 | AV13: 67 | AW13: 5 | AX13: 41 | AY13: 6 | AZ13: 3.4 | BA13: 2.07 | BB13: 10.29 | BC13: 67.4 | BD13: 0 | BE13: 504 | BF13: 0 | BG13: 69.33 | BH13: 3.76 | BI13: 0 | BJ13: 61 | BK13: 0 | BL13: 0 | BM13: 0 | BN13: 43817 | BO13: 4 | BP13: 1 | BQ13: 0 | BR13: 0 | BS13: 0 | BT13: 0 | BU13: 1 | BV13: 0 | BW13: 0 | BX13: 0 | BY13: 0 | BZ13: 0 | CA13: 0 | CB13: 1
A14: 2022年11月 | B14: B5 | C14: BF0001790E3 | D14: 4号冰箱#1-1-2-1 | E14: No T4PNK treatment | F14: TRUE | G14: FALSE | H14: GDM20230502-V_AAGGAGTA | I14: G2796 | J14: 肺动脉高压 | K14: 北京协和医院 | L14: 荆志成 | M14: Plasma | N14: 0 | O14: 0 | P14: S93 | Q14: AAGGAGTA | R14: 0 | S14: LXY | T14: 20230427 | U14: 8 | V14: 3.75 | W14: 30 | X14: 180 | Y14: 20230502 | Z14: V | AA14: Nova-seq | AB14: 0 | AC14: 海普洛斯 | AD14: 0 | AE14: IPAH/HPAH | AF14: bf0001790 | AG14: IPAH/HPAH | AH14: b1319 | AI14: 梁红霞 | AJ14: 42628 | AK14: 特发性肺动脉高压,慢性肺源性心脏病,心脏扩大,心包积液,心功能III级(NYHA分级),结缔组织病,肝功能异常 | AL14: 2 | AM14: 34 | AN14: 360 | AO14: 2 | AP14: 68 | AQ14: 166 | AR14: 1.85 | AS14: 0 | AT14: 103 | AU14: 73 | AV14: 77 | AW14: 9 | AX14: 62 | AY14: 11 | AZ14: 4.23 | BA14: 2.29 | BB14: 12.06 | BC14: 68.4 | BD14: 0 | BE14: 4360 | BF14: 0 | BG14: 84.31 | BH14: 6.96 | BI14: 0 | BJ14: 74 | BK14: 0 | BL14: 0 | BM14: 0 | BN14: 43818 | BO14: 4 | BP14: 1 | BQ14: 0 | BR14: 0 | BS14: 0 | BT14: 0 | BU14: 1 | BV14: 0 | BW14: 0 | BX14: 0 | BY14: 0 | BZ14: 0 | CA14: 1 | CB14: 1
A15: 2022年11月 | B15: B6 | C15: SVC001734E2 | D15: 4号冰箱#1-1-2-1 | E15: No T4PNK treatment | F15: TRUE | G15: FALSE | H15: GDM20230502-V_CTAAGCCT | I15: G2797 | J15: 肺动脉高压 | K15: 北京协和医院 | L15: 荆志成 | M15: Plasma | N15: 0 | O15: 0 | P15: S94 | Q15: CTAAGCCT | R15: 0 | S15: LXY | T15: 20230427 | U15: 7.42 | V15: 4.0431267 | W15: 30 | X15: 180 | Y15: 20230502 | Z15: V | AA15: Nova-seq | AB15: 0 | AC15: 海普洛斯 | AD15: 2022.11.11 | AE15: IPAH/HPAH | AF15: svc001734 | AG15: IPAH/HPAH | AH15: b3237 | AI15: 张丽 | AJ15: 42943 | AK15: 特发性肺动脉高压,心脏扩大,心功能Ⅱ级(NYHA分级) | AL15: 2 | AM15: 28 | AN15: 348 | AO15: 1 | AP15: 50 | AQ15: 162 | AR15: 1.6 | AS15: 0 | AT15: 102 | AU15: 66 | AV15: 75 | AW15: 2 | AX15: 52 | AY15: 6 | AZ15: 4.03 | BA15: 2.52 | BB15: 11.41 | BC15: 71.2 | BD15: 0 | BE15: 177 | BF15: 0 | BG15: 55.13 | BH15: 4.2 | BI15: 0 | BJ15: 45 | BK15: 0 | BL15: 0 | BM15: 0 | BN15: 43818 | BO15: 4 | BP15: 1 | BQ15: 0 | BR15: 0 | BS15: 0 | BT15: 0 | BU15: 1 | BV15: 0 | BW15: 0 | BX15: 0 | BY15: 0 | BZ15: 0 | CA15: 0 | CB15: 1
A16: 2022年11月 | B16: B7 | C16: BF0002929E3 | D16: 4号冰箱#1-1-2-1 | E16: No T4PNK treatment | F16: TRUE | G16: FALSE | H16: GDM20230502-V_TCTCTCCG | I16: G2798 | J16: 肺动脉高压 | K16: 北京协和医院 | L16: 荆志成 | M16: Plasma | N16: 0 | O16: 0 | P16: S95 | Q16: TCTCTCCG | R16: 0 | S16: LXY | T16: 20230427 | U16: 4.22 | V16: 7.1090047 | W16: 30 | X16: 180 | Y16: 20230502 | Z16: V | AA16: Nova-seq | AB16: 0 | AC16: 海普洛斯 | AD16: 2022.11.11 | AE16: IPAH/HPAH | AF16: bf0002929 | AG16: IPAH/HPAH | AH16: b1276 | AI16: 王秀芬 | AJ16: 42853 | AK16: 特发性肺动脉高压,心脏扩大,心功能Ⅱ--Ⅲ级(NYHA分级),冠状动脉粥样硬化,高脂血症 | AL16: 2 | AM16: 52 | AN16: 495 | AO16: 2 | AP16: 66 | AQ16: 155 | AR16: 1.75 | AS16: 0 | AT16: 135 | AU16: 78 | AV16: 101 | AW16: 6 | AX16: 64 | AY16: 9 | AZ16: 4.67 | BA16: 2.67 | BB16: 11.78 | BC16: 66 | BD16: 0 | BE16: 24 | BF16: 0 | BG16: 58.52 | BH16: 4.91 | BI16: 0 | BJ16: 56 | BK16: 0 | BL16: 0 | BM16: 0 | BN16: 43818 | BO16: 4 | BP16: 1 | BQ16: 0 | BR16: 0 | BS16: 1 | BT16: 0 | BU16: 0 | BV16: 0 | BW16: 0 | BX16: 0 | BY16: 0 | BZ16: 0 | CA16: 1 | CB16: 1
A17: 2022年11月 | B17: B8 | C17: BF0000459E2 | D17: 4号冰箱#1-1-2-1 | E17: No T4PNK treatment | F17: TRUE | G17: FALSE | H17: GDM20230502-V_GCGTAAGA | I17: G2799 | J17: 肺动脉高压 | K17: 北京协和医院 | L17: 荆志成 | M17: Plasma | N17: 0 | O17: 0 | P17: S96 | Q17: GCGTAAGA | R17: 0 | S17: LXY | T17: 20230427 | U17: 3.78 | V17: 7.9365079 | W17: 30 | X17: 180 | Y17: 20230502 | Z17: V | AA17: Nova-seq | AB17: 0 | AC17: 海普洛斯 | AD17: 0 | AE17: IPAH/HPAH | AF17: bf0000459 | AG17: IPAH/HPAH | AH17: b1697 | AI17: 王茹 | AJ17: 42272 | AK17: IPAH，APVT阳性 | AL17: 2 | AM17: 23 | AN17: 0 | AO17: 3 | AP17: 47 | AQ17: 162 | AR17: 1.49 | AS17: 53 | AT17: 102 | AU17: 75 | AV17: 78 | AW17: 13 | AX17: 44 | AY17: 9 | AZ17: 4.19 | BA17: 3.49 | BB17: 8.46 | BC17: 71.4 | BD17: 1 | BE17: 1901 | BF17: 0 | BG17: 0 | BH17: 0 | BI17: 0 | BJ17: 0 | BK17: 0 | BL17: 0 | BM17: 0 | BN17: 43829 | BO17: 2 | BP17: 0 | BQ17: 1 | BR17: 0 | BS17: 1 | BT17: 0 | BU17: 0 | BV17: 0 | BW17: 0 | BX17: 0 | BY17: 0 | BZ17: 0 | CA17: 1 | CB17: 1
A18: 2022年11月 | B18: B9 | C18: BF0003334E3 | D18: 4号冰箱#1-1-2-1 | E18: No T4PNK treatment | F18: TRUE | G18: FALSE | H18: GDM20230502-V_TAGATCGC | I18: G2800 | J18: 肺动脉高压 | K18: 北京协和医院 | L18: 荆志成 | M18: Plasma | N18: 0 | O18: 0 | P18: S97 | Q18: TAGATCGC | R18: 0 | S18: LXY | T18: 20230427 | U18: 5.14 | V18: 5.8365759 | W18: 30 | X18: 180 | Y18: 20230502 | Z18: V | AA18: Nova-seq | AB18: 0 | AC18: 海普洛斯 | AD18: 2022.11.11 | AE18: IPAH/HPAH | AF18: bf0003334 | AG18: IPAH/HPAH | AH18: b495 | AI18: 李芬 | AJ18: 42907 | AK18: 原发性肺动脉高压(特发性),心脏扩大,心功能Ⅲ级 | AL18: 2 | AM18: 43 | AN18: 340 | AO18: 2 | AP18: 40 | AQ18: 150 | AR18: 1.4 | AS18: 0 | AT18: 119 | AU18: 81 | AV18: 75 | AW18: 8 | AX18: 46 | AY18: 11 | AZ18: 2.28 | BA18: 1.63 | BB18: 15.35 | BC18: 59.7 | BD18: 0 | BE18: 981.2 | BF18: 0 | BG18: 63 | BH18: 3.29 | BI18: 1 | BJ18: 55 | BK18: 0 | BL18: 1 | BM18: 43439 | BN18: 0 | BO18: 4 | BP18: 1 | BQ18: 0 | BR18: 0 | BS18: 0 | BT18: 0 | BU18: 1 | BV18: 0 | BW18: 0 | BX18: 0 | BY18: 0 | BZ18: 0 | CA18: 1 | CB18: 1
A19: 2022年11月 | B19: C1 | C19: BF0001995E4 | D19: 4号冰箱#1-1-2-1 | E19: No T4PNK treatment | F19: TRUE | G19: FALSE | H19: GDM20230502-V_CTCTCTAT | I19: G2801 | J19: 肺动脉高压 | K19: 北京协和医院 | L19: 荆志成 | M19: Plasma | N19: 0 | O19: 0 | P19: S98 | Q19: CTCTCTAT | R19: 0 | S19: LXY | T19: 20230427 | U19: 6.06 | V19: 4.950495 | W19: 30 | X19: 180 | Y19: 20230502 | Z19: V | AA19: Nova-seq | AB19: 0 | AC19: 海普洛斯 | AD19: 2022.11.11 | AE19: IPAH/HPAH | AF19: bf0001995 | AG19: IPAH/HPAH | AH19: b2604 | AI19: 丁清丽 | AJ19: 42686 | AK19: 特发性肺动脉高压,心脏扩大,心功能III级(NYHA分级) | AL19: 2 | AM19: 23 | AN19: 540 | AO19: 2 | AP19: 69 | AQ19: 183 | AR19: 1.96 | AS19: 0 | AT19: 93 | AU19: 60 | AV19: 93 | AW19: 3 | AX19: 71 | AY19: 7 | AZ19: 3.03 | BA19: 1.55 | BB19: 21.12 | BC19: 62.4 | BD19: 0 | BE19: 6524 | BF19: 0 | BG19: 56.55 | BH19: 5.5 | BI19: 0 | BJ19: 56 | BK19: 0 | BL19: 0 | BM19: 0 | BN19: 43817 | BO19: 3 | BP19: 0 | BQ19: 0 | BR19: 1 | BS19: 0 | BT19: 0 | BU19: 1 | BV19: 0 | BW19: 1 | BX19: 0 | BY19: 0 | BZ19: 1 | CA19: 1 | CB19: 1
A20: 2022年11月 | B20: C2 | C20: BF0003671E2 | D20: 4号冰箱#1-1-2-1 | E20: No T4PNK treatment | F20: TRUE | G20: FALSE | H20: GDM20230502-V_AGAGTAGA | I20: G2802 | J20: 肺动脉高压 | K20: 北京协和医院 | L20: 荆志成 | M20: Plasma | N20: 0 | O20: 0 | P20: S99 | Q20: AGAGTAGA | R20: 0 | S20: LXY | T20: 20230427 | U20: 6.24 | V20: 4.8076923 | W20: 30 | X20: 180 | Y20: 20230502 | Z20: V | AA20: Nova-seq | AB20: 0 | AC20: 海普洛斯 | AD20: 2022.11.11 | AE20: IPAH/HPAH | AF20: bf0003671 | AG20: IPAH/HPAH | AH20: b367 | AI20: 赵梓轶 | AJ20: 42973 | AK20: 特发性肺动脉高压 | AL20: 2 | AM20: 9 | AN20: 0 | AO20: 0 | AP20: 30 | AQ20: 143 | AR20: 1.23 | AS20: 0 | AT20: 115 | AU20: 67 | AV20: 104 | AW20: 6 | AX20: 35 | AY20: 11 | AZ20: 5.67 | BA20: 4.61 | BB20: 4.23 | BC20: 81.1 | BD20: 0 | BE20: 0 | BF20: 0 | BG20: 0 | BH20: 0 | BI20: 0 | BJ20: 0 | BK20: 0 | BL20: 0 | BM20: 0 | BN20: 0 | BO20: 0 | BP20: 0 | BQ20: 0 | BR20: 0 | BS20: 0 | BT20: 0 | BU20: 0 | BV20: 0 | BW20: 0 | BX20: 0 | BY20: 0 | BZ20: 0 | CA20: 0 | CB20: 0
A21: 2022年11月 | B21: C3 | C21: BF0003467E1 | D21: 4号冰箱#1-1-2-1 | E21: No T4PNK treatment | F21: TRUE | G21: FALSE | H21: GDM20230502-V_AGCGTAGC | I21: G2803 | J21: 肺动脉高压 | K21: 北京协和医院 | L21: 荆志成 | M21: Plasma | N21: 0 | O21: 0 | P21: S25 | Q21: AGCGTAGC | R21: 0 | S21: LXY | T21: 20230427 | U21: 9.22 | V21: 3.2537961 | W21: 30 | X21: 180 | Y21: 20230502 | Z21: V | AA21: Nova-seq | AB21: 0 | AC21: 海普洛斯 | AD21: 2022.11.11 | AE21: IPAH/HPAH | AF21: bf0003467 | AG21: IPAH/HPAH | AH21: b1949 | AI21: 曹永玲 | AJ21: 42944 | AK21: 特发性肺动脉高压,慢性肺源性心脏病,心脏扩大,心功能III级(NYHA分级),子宫良性肿瘤 | AL21: 2 | AM21: 38 | AN21: 330 | AO21: 2 | AP21: 47 | AQ21: 154 | AR21: 1.51 | AS21: 0 | AT21: 90 | AU21: 49 | AV21: 71 | AW21: 3 | AX21: 72 | AY21: 7 | AZ21: 3.4 | BA21: 2.25 | BB21: 19.12 | BC21: 70.8 | BD21: 0 | BE21: 613 | BF21: 0 | BG21: 50.58 | BH21: 4.71 | BI21: 0 | BJ21: 65 | BK21: 0 | BL21: 0 | BM21: 0 | BN21: 43817 | BO21: 2 | BP21: 0 | BQ21: 1 | BR21: 0 | BS21: 0 | BT21: 0 | BU21: 1 | BV21: 1 | BW21: 0 | BX21: 0 | BY21: 0 | BZ21: 0 | CA21: 0 | CB21: 0
A22: 2022年11月 | B22: C4 | C22: BF0005110E4 | D22: 4号冰箱#1-1-2-1 | E22: No T4PNK treatment | F22: TRUE | G22: FALSE | H22: GDM20230502-V_TCGCCTTA | I22: G2804 | J22: 肺动脉高压 | K22: 北京协和医院 | L22: 荆志成 | M22: Plasma | N22: 0 | O22: 0 | P22: S37 | Q22: TCGCCTTA | R22: 0 | S22: LXY | T22: 20230427 | U22: 4.38 | V22: 6.8493151 | W22: 30 | X22: 180 | Y22: 20230502 | Z22: V | AA22: Nova-seq | AB22: 0 | AC22: 海普洛斯 | AD22: 2022.11.11 | AE22: IPAH/HPAH | AF22: bf0005110 | AG22: IPAH/HPAH | AH22: b1534 | AI22: 邢秀芬 | AJ22: 43243 | AK22: 特发性肺动脉高压,心脏扩大,卵圆孔未闭,心功能III级(NYHA分级),高血压 | AL22: 2 | AM22: 50 | AN22: #NULL! | AO22: 2 | AP22: 55 | AQ22: 165 | AR22: 1.68 | AS22: 0 | AT22: 106 | AU22: 65 | AV22: 88 | AW22: 4 | AX22: 64 | AY22: 11 | AZ22: 3.26 | BA22: 1.94 | BB22: 16.24 | BC22: 56.5 | BD22: 0 | BE22: 4910 | BF22: 0 | BG22: 79.9 | BH22: 7.77 | BI22: 0 | BJ22: 71 | BK22: 0 | BL22: 0 | BM22: 0 | BN22: 43818 | BO22: 2 | BP22: 0 | BQ22: 1 | BR22: 0 | BS22: 0 | BT22: 0 | BU22: 1 | BV22: 0 | BW22: 0 | BX22: 0 | BY22: 1 | BZ22: 0 | CA22: 1 | CB22: 1
A23: 2022年11月 | B23: C5 | C23: BF0000336E1 | D23: 4号冰箱#1-1-2-1 | E23: No T4PNK treatment | F23: TRUE | G23: FALSE | H23: GDM20230512-I_CTAGTACG | I23: G2805 | J23: 肺动脉高压 | K23: 北京协和医院 | L23: 荆志成 | M23: Plasma | N23: 0 | O23: 0 | P23: s39 | Q23: CTAGTACG | R23: 0 | S23: LXY | T23: 20230503 | U23: 3.06 | V23: 9.8039216 | W23: 30 | X23: 192 | Y23: 20230512 | Z23: I | AA23: Nova-seq | AB23: 6 | AC23: 海普洛斯 | AD23: 0 | AE23: CHD-ASD-PH | AF23: bf0000336 | AG23: CHD-ASD-PH | AH23: b1622 | AI23: 郭子雅 | AJ23: 42235 | AK23: 先天性心脏病，房间隔缺损（II孔中央型6mm），肺动脉高压 | AL23: 2 | AM23: 4 | AN23: 0 | AO23: 0 | AP23: 20 | AQ23: 116 | AR23: 0.95 | AS23: 0 | AT23: 99 | AU23: 52 | AV23: 113 | AW23: 7 | AX23: 68 | AY23: 15 | AZ23: 6.78 | BA23: 0 | BB23: 0 | BC23: 0 | BD23: 0 | BE23: 0 | BF23: 0 | BG23: 0 | BH23: 0 | BI23: 0 | BJ23: 0 | BK23: 0 | BL23: 0 | BM23: 0 | BN23: 0 | BO23: 0 | BP23: 0 | BQ23: 0 | BR23: 0 | BS23: 0 | BT23: 0 | BU23: 0 | BV23: 0 | BW23: 0 | BX23: 0 | BY23: 0 | BZ23: 0 | CA23: 0 | CB23: 0
A24: 2022年11月 | B24: C7 | C24: BF0007125E4 | D24: 4号冰箱#1-1-2-1 | E24: No T4PNK treatment | F24: TRUE | G24: FALSE | H24: GDM20230512-I_GCTCAGGA | I24: G2807 | J24: 肺动脉高压 | K24: 北京协和医院 | L24: 荆志成 | M24: Plasma | N24: 0 | O24: 0 | P24: s43 | Q24: GCTCAGGA | R24: 0 | S24: LXY | T24: 20230503 | U24: 5.96 | V24: 5.033557 | W24: 30 | X24: 192 | Y24: 20230512 | Z24: I | AA24: Nova-seq | AB24: 6 | AC24: 海普洛斯 | AD24: 2022.11.11 | AE24: IPAH/HPAH | AF24: bf0007125 | AG24: IPAH/HPAH | AH24: b2033 | AI24: 张明谦 | AJ24: 43609 | AK24: 肺动脉高压,心脏扩大,心功能III级(NYHA分级),肺静脉闭塞,肺毛细血管瘤样病变,高血压 | AL24: 1 | AM24: 23 | AN24: #NULL! | AO24: 2 | AP24: 97 | AQ24: 172 | AR24: 2.24 | AS24: 0 | AT24: 119 | AU24: 90 | AV24: 84 | AW24: 10 | AX24: 100 | AY24: 9 | AZ24: 2.82 | BA24: 1.26 | BB24: 32.98 | BC24: 54.3 | BD24: 0 | BE24: 2128 | BF24: 0 | BG24: 93.32 | BH24: 5.65 | BI24: 0 | BJ24: 64 | BK24: 0 | BL24: 0 | BM24: 0 | BN24: 43830 | BO24: 2 | BP24: 0 | BQ24: 1 | BR24: 0 | BS24: 0 | BT24: 0 | BU24: 1 | BV24: 0 | BW24: 1 | BX24: 0 | BY24: 0 | BZ24: 0 | CA24: 1 | CB24: 1
A25: 2022年11月 | B25: D1 | C25: BF0005442E5 | D25: 4号冰箱#1-1-2-1 | E25: No T4PNK treatment | F25: TRUE | G25: FALSE | H25: GDM20230512-I_GTAGAGAG | I25: G2810 | J25: 肺动脉高压 | K25: 北京协和医院 | L25: 荆志成 | M25: Plasma | N25: 0 | O25: 0 | P25: s49 | Q25: GTAGAGAG | R25: 0 | S25: LXY | T25: 20230503 | U25: 7.78 | V25: 3.8560411 | W25: 30 | X25: 192 | Y25: 20230512 | Z25: I | AA25: Nova-seq | AB25: 6 | AC25: 海普洛斯 | AD25: 2022.11.11 | AE25: IPAH/HPAH | AF25: bf0005442 | AG25: IPAH/HPAH | AH25: b3995 | AI25: 曾晗祥璇 | AJ25: 43296 | AK25: 特发性肺动脉高压，慢性肺源性心脏病，心脏扩大 | AL25: 2 | AM25: 18 | AN25: 333 | AO25: 2 | AP25: 46 | AQ25: 161 | AR25: 1.54 | AS25: 0 | AT25: 94 | AU25: 71 | AV25: 111 | AW25: 4 | AX25: 57 | AY25: 5 | AZ25: 4.57 | BA25: 2.96 | BB25: 11.38 | BC25: 74.2 | BD25: 未见APVT试验 | BE25: 101 | BF25: 0 | BG25: 90.67 | BH25: 6.8 | BI25: 0 | BJ25: 0 | BK25: 0 | BL25: 0 | BM25: 0 | BN25: 0 | BO25: 0 | BP25: 0 | BQ25: 0 | BR25: 0 | BS25: 0 | BT25: 0 | BU25: 0 | BV25: 0 | BW25: 0 | BX25: 0 | BY25: 0 | BZ25: 0 | CA25: 0 | CB25: 0
A26: 2022年11月 | B26: D2 | C26: svc001619e5 | D26: 4号冰箱#1-1-2-1 | E26: No T4PNK treatment | F26: TRUE | G26: FALSE | H26: GDM20230512-I_CCTCTCTG | I26: G2811 | J26: 肺动脉高压 | K26: 北京协和医院 | L26: 荆志成 | M26: Plasma | N26: 0 | O26: 0 | P26: S88 | Q26: CCTCTCTG | R26: 0 | S26: LXY | T26: 20230504 | U26: 3.06 | V26: 9.8039216 | W26: 30 | X26: 192 | Y26: 20230512 | Z26: I | AA26: Nova-seq | AB26: 6 | AC26: 海普洛斯 | AD26: 0 | AE26: IPAH/HPAH | AF26: svc001619 | AG26: IPAH/HPAH | AH26: b3161 | AI26: 沙保娟 | AJ26: 42908 | AK26: 特发性肺动脉高压,心脏扩大,三尖瓣关闭不全,心功能III级(NYHA分级),功能性子宫出血 | AL26: 2 | AM26: 31 | AN26: #NULL! | AO26: 2 | AP26: 52.5 | AQ26: 163 | AR26: 1.64 | AS26: 0 | AT26: 102 | AU26: 66 | AV26: 55 | AW26: 7 | AX26: 38 | AY26: 8 | AZ26: 3.53 | BA26: 2.15 | BB26: 8.78 | BC26: 63.3 | BD26: 0 | BE26: 711 | BF26: 0 | BG26: 83.48 | BH26: 6 | BI26: 0 | BJ26: 47 | BK26: 0 | BL26: 0 | BM26: 0 | BN26: 43822 | BO26: 2 | BP26: 0 | BQ26: 1 | BR26: 0 | BS26: 0 | BT26: 0 | BU26: 1 | BV26: 0 | BW26: 1 | BX26: 0 | BY26: 0 | BZ26: 0 | CA26: 0 | CB26: 1
A27: 2022年11月 | B27: D3 | C27: BF0001366E2 | D27: 4号冰箱#1-1-2-1 | E27: No T4PNK treatment | F27: TRUE | G27: FALSE | H27: GDM20230512-I_CAGCCTCG | I27: G2812 | J27: 肺动脉高压 | K27: 北京协和医院 | L27: 荆志成 | M27: Plasma | N27: 0 | O27: 0 | P27: S89 | Q27: CAGCCTCG | R27: 0 | S27: LXY | T27: 20230504 | U27: 8.6 | V27: 3.4883721 | W27: 30 | X27: 192 | Y27: 20230512 | Z27: I | AA27: Nova-seq | AB27: 6 | AC27: 海普洛斯 | AD27: 0 | AE27: IPAH/HPAH | AF27: bf0001366 | AG27: IPAH/HPAH | AH27: 27 | AI27: 张静函 | AJ27: 42534 | AK27: ipah | AL27: 2 | AM27: 25 | AN27: 0 | AO27: 0 | AP27: 49 | AQ27: 164 | AR27: 1.6 | AS27: 0 | AT27: 99 | AU27: 65 | AV27: 82 | AW27: 11 | AX27: 67 | AY27: 10 | AZ27: 4.13 | BA27: 2.58 | BB27: 13.8 | BC27: 69.4 | BD27: 未见APVT试验 | BE27: 0 | BF27: 0 | BG27: 0 | BH27: 0 | BI27: 0 | BJ27: 0 | BK27: 0 | BL27: 0 | BM27: 0 | BN27: 0 | BO27: 0 | BP27: 0 | BQ27: 0 | BR27: 0 | BS27: 0 | BT27: 0 | BU27: 0 | BV27: 0 | BW27: 0 | BX27: 0 | BY27: 0 | BZ27: 0 | CA27: 0 | CB27: 0
A28: 2022年11月 | B28: D5 | C28: BF0002090E1 | D28: 4号冰箱#1-1-2-1 | E28: No T4PNK treatment | F28: TRUE | G28: FALSE | H28: GDM20230512-I_TCCTCTAC | I28: G2814 | J28: 肺动脉高压 | K28: 北京协和医院 | L28: 荆志成 | M28: Plasma | N28: 0 | O28: 0 | P28: S91 | Q28: TCCTCTAC | R28: 0 | S28: LXY | T28: 20230504 | U28: 6.68 | V28: 4.491018 | W28: 30 | X28: 192 | Y28: 20230512 | Z28: I | AA28: Nova-seq | AB28: 6 | AC28: 海普洛斯 | AD28: 2022.11.11 | AE28: IPAH/HPAH | AF28: bf0002090 | AG28: IPAH/HPAH | AH28: b2663 | AI28: 吴亚涛 | AJ28: 42703 | AK28: ipah,pvod待除外 | AL28: 1 | AM28: 16 | AN28: 520 | AO28: 2 | AP28: 62 | AQ28: 174 | AR28: 1.82 | AS28: 0 | AT28: 112 | AU28: 51 | AV28: 68 | AW28: 4 | AX28: 51 | AY28: 9 | AZ28: 6.93 | BA28: 3.81 | BB28: 6.06 | BC28: 72.6 | BD28: 0 | BE28: 19 | BF28: 0 | BG28: 63.33 | BH28: 5.11 | BI28: 0 | BJ28: 0 | BK28: 0 | BL28: 0 | BM28: 0 | BN28: 43830 | BO28: 0 | BP28: 0 | BQ28: 0 | BR28: 0 | BS28: 0 | BT28: 0 | BU28: 0 | BV28: 0 | BW28: 0 | BX28: 0 | BY28: 0 | BZ28: 0 | CA28: 0 | CB28: 0
A29: 2022年11月 | B29: D6 | C29: BF0004516E3 | D29: 4号冰箱#1-1-2-1 | E29: No T4PNK treatment | F29: TRUE | G29: FALSE | H29: GDM20230512-I_ACTGCATA | I29: G2815 | J29: 肺动脉高压 | K29: 北京协和医院 | L29: 荆志成 | M29: Plasma | N29: 0 | O29: 0 | P29: S92 | Q29: ACTGCATA | R29: 0 | S29: LXY | T29: 20230504 | U29: 5.88 | V29: 5.1020408 | W29: 30 | X29: 192 | Y29: 20230512 | Z29: I | AA29: Nova-seq | AB29: 6 | AC29: 海普洛斯 | AD29: 2022.11.11 | AE29: IPAH/HPAH | AF29: bf0004516 | AG29: IPAH/HPAH | AH29: b3656 | AI29: 王富娟 | AJ29: 43133 | AK29: 特发性肺动脉高压,心脏扩大,非风湿性三尖瓣关闭不全,心功能Ⅱ级(NYHA分级) | AL29: 2 | AM29: 37 | AN29: 482 | AO29: 1 | AP29: 66 | AQ29: 164 | AR29: 1.81 | AS29: 0 | AT29: 101 | AU29: 65 | AV29: 71 | AW29: 4 | AX29: 73 | AY29: 8 | AZ29: 4.93 | BA29: 2.73 | BB29: 13.18 | BC29: 68.8 | BD29: 0 | BE29: 980 | BF29: 0 | BG29: 62 | BH29: 4 | BI29: 0 | BJ29: 39 | BK29: 0 | BL29: 0 | BM29: 0 | BN29: 43791 | BO29: 2 | BP29: 0 | BQ29: 1 | BR29: 0 | BS29: 0 | BT29: 0 | BU29: 1 | BV29: 0 | BW29: 1 | BX29: 0 | BY29: 0 | BZ29: 0 | CA29: 1 | CB29: 1
A30: 2022年11月 | B30: D7 | C30: BF0004484E1 | D30: 4号冰箱#1-1-2-1 | E30: No T4PNK treatment | F30: TRUE | G30: FALSE | H30: GDM20230512-I_AAGGAGTA | I30: G2816 | J30: 肺动脉高压 | K30: 北京协和医院 | L30: 荆志成 | M30: Plasma | N30: 0 | O30: 0 | P30: S93 | Q30: AAGGAGTA | R30: 0 | S30: LXY | T30: 20230504 | U30: 11.1 | V30: 2.7027027 | W30: 30 | X30: 192 | Y30: 20230512 | Z30: I | AA30: Nova-seq | AB30: 6 | AC30: 海普洛斯 | AD30: 2022.11.11 | AE30: IPAH/HPAH | AF30: bf0004484 | AG30: IPAH/HPAH | AH30: b3645 | AI30: 栾勇 | AJ30: 43130 | AK30: ipah\慢性肺源性心脏病\卵圆孔未闭\心律失常\室性期前收缩\短阵室性心动过速\咯血\aps待除外、双侧大脑后动脉狭窄、双侧大脑中动脉斑块、右侧椎动脉狭窄、陈旧性脑梗死 | AL30: 1 | AM30: 46 | AN30: 0 | AO30: 3 | AP30: 58 | AQ30: 170 | AR30: 1.75 | AS30: 0 | AT30: 129 | AU30: 89 | AV30: 92 | AW30: 7 | AX30: 52 | AY30: 9 | AZ30: 4.17 | BA30: 3.29 | BB30: 10.31 | BC30: 66.5 | BD30: 0 | BE30: 0 | BF30: 0 | BG30: 0 | BH30: 0 | BI30: 0 | BJ30: 0 | BK30: 0 | BL30: 0 | BM30: 0 | BN30: 43791 | BO30: 0 | BP30: 0 | BQ30: 0 | BR30: 0 | BS30: 0 | BT30: 0 | BU30: 0 | BV30: 0 | BW30: 0 | BX30: 0 | BY30: 0 | BZ30: 0 | CA30: 0 | CB30: 0
A31: 2022年11月 | B31: D8 | C31: BF0005080E1 | D31: 4号冰箱#1-1-2-1 | E31: No T4PNK treatment | F31: TRUE | G31: FALSE | H31: GDM20230512-I_CTAAGCCT | I31: G2817 | J31: 肺动脉高压 | K31: 北京协和医院 | L31: 荆志成 | M31: Plasma | N31: 0 | O31: 0 | P31: S94 | Q31: CTAAGCCT | R31: 0 | S31: LXY | T31: 20230504 | U31: 7.56 | V31: 3.968254 | W31: 30 | X31: 192 | Y31: 20230512 | Z31: I | AA31: Nova-seq | AB31: 6 | AC31: 海普洛斯 | AD31: 2022.11.11 | AE31: IPAH/HPAH | AF31: bf0005080 | AG31: IPAH/HPAH | AH31: b1146 | AI31: 张巧巧 | AJ31: 43240 | AK31: 可遗传性肺动脉高压,心脏扩大,心功能Ⅱ--Ⅲ级(NYHA分级) | AL31: 2 | AM31: 33 | AN31: 390 | AO31: 2 | AP31: 50 | AQ31: 150 | AR31: 1.53 | AS31: 0 | AT31: 121 | AU31: 77 | AV31: 94 | AW31: 6 | AX31: 69 | AY31: 9 | AZ31: 3.73 | BA31: 2.43 | BB31: 16.09 | BC31: 67.8 | BD31: 0 | BE31: 554 | BF31: 0 | BG31: 60.85 | BH31: 4.7 | BI31: 0 | BJ31: 77 | BK31: 0 | BL31: 0 | BM31: 0 | BN31: 43829 | BO31: 4 | BP31: 1 | BQ31: 0 | BR31: 0 | BS31: 0 | BT31: 0 | BU31: 1 | BV31: 0 | BW31: 0 | BX31: 0 | BY31: 0 | BZ31: 0 | CA31: 1 | CB31: 1
A32: 2022年11月 | B32: D9 | C32: BF0003014E3 | D32: 4号冰箱#1-1-2-1 | E32: No T4PNK treatment | F32: TRUE | G32: FALSE | H32: GDM20230512-I_TCTCTCCG | I32: G2818 | J32: 肺动脉高压 | K32: 北京协和医院 | L32: 荆志成 | M32: Plasma | N32: 0 | O32: 0 | P32: S95 | Q32: TCTCTCCG | R32: 0 | S32: LXY | T32: 20230504 | U32: 8.64 | V32: 3.4722222 | W32: 30 | X32: 192 | Y32: 20230512 | Z32: I | AA32: Nova-seq | AB32: 6 | AC32: 海普洛斯 | AD32: 2022.11.11 | AE32: IPAH/HPAH | AF32: bf0003014 | AG32: IPAH/HPAH | AH32: b850 | AI32: 刘思源 | AJ32: 42873 | AK32: 特发性肺动脉高压,心功能I级(NYHA分级),高脂血症 | AL32: 2 | AM32: 29 | AN32: 588 | AO32: 1 | AP32: 80 | AQ32: 173 | AR32: 2.04 | AS32: 0 | AT32: 98 | AU32: 63 | AV32: 80 | AW32: 3 | AX32: 27 | AY32: 5 | AZ32: 7.37 | BA32: 3.61 | BB32: 2.99 | BC32: 76.8 | BD32: 1 | BE32: 16 | BF32: 0 | BG32: 60.38 | BH32: 2.7 | BI32: 0 | BJ32: 48 | BK32: 0 | BL32: 0 | BM32: 0 | BN32: 43791 | BO32: 4 | BP32: 1 | BQ32: 0 | BR32: 0 | BS32: 0 | BT32: 0 | BU32: 0 | BV32: 0 | BW32: 0 | BX32: 0 | BY32: 0 | BZ32: 0 | CA32: 0 | CB32: 0
